Workbook

Sheet Final Incentives CO,LOS and LO
E2: 45
E3: 90
C4: =SUBTOTAL(9,C6:C192) -> 43862 | D4: =SUBTOTAL(9,D6:D211) -> 13895 | E4: =SUBTOTAL(9,E6:E211) -> 7857
A5: Branch | B5: Name | C5: Incentives | D5: Transportation | E5: Bonus
A6: Basra | B6: Ahmed Abdul Hussain Mathkor | C6: 241 | D6: 90 | E6: 0
A7: Basra | B7: Ali Abdul Khaliq Yousif | C7: 299 | D7: 70 | E7: 0
A8: Basra | B8: Ali Abdul Zahra Jasim | C8: 400 | D8: 150 | E8: 0
A9: Basra | B9: ali aziz abdul hafeth | C9: 189 | D9: 70 | E9: 0
A10: Basra | B10: Ali Kadhum Wshah | C10: 0 | D10: 75 | E10: 24
A11: Basra | B11: Eman Yaarub Abdul Jalil | C11: 0 | D11: 80 | E11: 0
A12: Basra | B12: Ahmad Hatrosh Muhammad | C12: 598 | D12: 90 | E12: 0
A13: Basra | B13: Hussain Jawad Kadhum | C13: 0 | D13: 80 | E13: 0
A14: Basra | B14: Hussein Mustafa Abdul Samad | C14: 0 | D14: 80 | E14: 0
A15: Basra | B15: Idrees Hassan Kadhum | C15: 0 | D15: 75 | E15: 22
A16: Basra | B16: Muhammad Hazim Majeed | C16: 150 | D16: 80 | E16: 0
A17: Basra | B17: Muhammad Majeed Ubaid | C17: 0 | D17: 80 | E17: 0
... A142: Dewaniya | B142: Ammar Jawad hasan | C142: 385 | D142: 50 | E142: 0
A143: Wehda | B143: Ezat Shamkhy Jaber | C143: 786 | E143: 0
A144: Wehda | B144: Alaa Kamil Qassim | C144: 633 | D144: 50 | E144: 0
A145: Hindiyah | B145: Mustafa Sabeeh Hadi | C145: 671 | D145: 350 | E145: 0
A146: Basra | B146: Ali Yousif Eesa | C146: 413 | E146: 176
A147: Basra | B147: Jaafar Muneer Haleem | C147: 302 | E147: 1211
A148: Dewaniya | B148: Amer Ahmed AbdulWahid | C148: 508 | E148: 75
A149: Hashimiyah | B149: Hayder Hussein Obayes | C149: 692 | E149: 75
A150: Hilla | B150: Hassanein Kadhum Abid | C150: 395 | E150: 187
A151: Hilla | B151: Muhammad Qahtan Mindeel | C151: 441 | E151: 192
A152: Hindiyah | B152: Yais Khdhir Dikhi | C152: 543 | E152: 75
A153: Karbala | B153: Ali Manji Oufi | C153: 492 | E153: 209
A154: Karbala | B154: Mohammed Abid Al Sada Issa | C154: 686 | E154: 248
A155: Kut | B155: Hassan Razaq Sebah | C155: 478 | E155: 80
A156: Kut | B156: Hayder Talib Hashim | C156: 656 | E156: 83
A157: Mansour | B157: Hussain Taher Fezaa | C157: 689 | E157: 196
... A163: Najaf | B163: Azhar Hassan Hussien | C163: 334 | E163: 163
A164: Nasriya | B164: Adel Abdul Ameer Farhood | C164: 490 | D164: 250 | E164: 544
A165: Nasriya | B165: Ahmed Hadi Muhammed | C165: 552 | E165: 123
A166: Sulymaniya | B166: Azad Kareem Muhammed | C166: 106 | E166: 30
A167: Wehda | B167: Ali Mehdi Dawood | C167: 316 | E167: 156
A168: Wehda | B168: Ali Salman Ali | C168: 635 | E168: 167
A169: Wehda | B169: Mahir Kareem Hussain | C169: 182 | E169: 68
A170: Basra | B170: Sajad Abdul Hussain Abdul Raheem | C170: 0 | D170: 70 | E170: 87
...

Sheet CO Incentive
E1: Micro | F1: =COUNTIFS(LO!B$7:B$288,$E1) -> 75 | W1: Actual | X1: Target | AB1: Weight | AC1: Points | AD1: 10 | AE1: 0 | AF1: 25 | AG1: 0 | AH1: 15 | AI1: 40 | AJ1: 5 | AK1: 5 | AL1: 0 | AM1: =SUM(AD1:AL1) -> 100 | AN1: BenchMark | AO1: 50 | AP1: Maximum Increase | AQ1: 0
E2: SE | F2: =COUNTIFS(LO!B$7:B$288,$E2) -> 9 | G2: Monthly Target | J2: Monthly Target | M2: Monthly Target | P2: Monthly Target | V2: Micro | W2: =LO!W2 -> 168.26667 | X2: ='LOS Incentive'!V3 -> 250 | Y2: =SUBTOTAL(101,Z$7:Z$51) -> #DIV/0! | AA2: =SUBTOTAL(101,AB$7:AB$51) -> #DIV/0! | AB2: Max Input | AC2: Full Points @ | AD2: 1 | AE2: 1 | AF2: 1 | AG2: 1 | AH2: 0.02 | AI2: 0.05 | AJ2: 1 | AK2: 0.7 | AL2: 0.3 | AM2: =AVERAGE(AM7:AM13) -> #DIV/0! | AP2: Maximum Deducation | AQ2: -400
E3: =SUBTOTAL(109,E$7:E$13) -> 88 | F3: =SUBTOTAL(109,F$7:F$13) -> 54922713 | G3: =SUBTOTAL(109,G$7:G$13) -> 56444444 | I3: =SUBTOTAL(109,I$7:I$13) -> 15068 | J3: =SUBTOTAL(109,J$7:J$13) -> 45823 | L3: =SUBTOTAL(109,L$7:L$13) -> 4087083.3 | M3: =SUBTOTAL(109,M$7:M$13) -> 5909090.7 | O3: =SUBTOTAL(109,O$7:O$13) -> 778 | P3: =SUBTOTAL(109,P$7:P$13) -> 1037 | R3: =SUBTOTAL(109,R$7:R$13) -> 776 | S3: =SUBTOTAL(109,S$7:S$13) -> 403 | U3: =SUBTOTAL(109,U$7:U$13) -> 317 | V3: SE | W3: =LO!W3 -> 76.555556 | X3: ='LOS Incentive'!V4 -> 100 | Y3: =SUBTOTAL(109,Y$7:Y$51) -> 1470247.7 | AA3: =SUBTOTAL(109,AA$7:AA$51) -> 1134051.8 | AB3: Min Input | AC3: Zero Point @ | AD3: 0.7 | AE3: 0.8 | AF3: 0.7 | AG3: 0.5 | AH3: 0.07 | AI3: 0.15 | AJ3: 0.5 | AK3: 0.2 | AL3: 0 | AO3: 0.7 | AP3: =100%-AO3 -> 0.3 | AS3: =AS5 -> #DIV/0!
AC4: If Obove Full
AC5: If Less Than Zero | AN5: =SUBTOTAL(109,AN7:AN313) -> 13688 | AO5: =SUBTOTAL(109,AO7:AO313) -> 9779 | AP5: =SUBTOTAL(109,AP7:AP313) -> 4104 | AQ5: =SUBTOTAL(109,AQ7:AQ313) -> #DIV/0! | AR5: =SUBTOTAL(109,AR7:AR313) -> #DIV/0! | AS5: =SUBTOTAL(109,AS7:AS313) -> #DIV/0! | AT5: =SUBTOTAL(101,AT7:AT313) -> #DIV/0!
A6: Credit Coordinator | D6: Branch | E6: Number of Staff. | F6: Actual Portfolio | G6: Target Portfolio | H6: Actual/Target | I6: Actual Active Clients | J6: Target Active Clients | K6: Actual/Target | L6: Actual Disbursement $ | M6: Tatget Disbursement $ | N6: Actual/Target | O6: Actual Disbursement # | P6: Tatget Disbursement # | Q6: Actual/Target | R6: Disb Clients No. | S6: Disb ReNew No. Clients | T6: Disb Renewal Rate (%) | U6: Disb Female No. Clients | V6: Disb Female Rate (%) | W6: Active Clients | X6: Case Load by LO | Y6: PAR $ 0-30 | Z6: PAR 0-30 | AA6: PAR $ >30 | AB6: PAR >30 | AD6: Portfolio Share | AE6: Active Clients Share | AF6: Disbursement $ Share | AG6: Disbursement # Portion | AH6: PAR 1-30 | AI6: PAR >30 | AJ6: Case Load | AK6: Renewal Rate | AL6: Female Rate | AM6: Total | AN6: Salaries | AO6: Basic | AP6: Net | AQ6: Proposal Incentive | AR6: Proposal Total Salary | AS6: Difference | AT6: New/Old Salary
A7: Khalid Musa Jumaa | D7: Nasriya | E7: =COUNTIFS(LO!E:E,$A7) -> 0 | F7: =SUMIFS(LO!F:F,LO!$E:$E,$A7) -> 0 | G7: =SUMIFS(LO!G:G,LO!$E:$E,$A7) -> 0 | H7: =F7/G7 -> #DIV/0! | I7: =SUMIFS(LO!I:I,LO!$E:$E,$A7) -> 0 | J7: =SUMIFS(LO!J:J,LO!$E:$E,$A7) -> 0 | K7: =I7/J7 -> #DIV/0! | L7: =SUMIFS(LO!L:L,LO!$E:$E,$A7) -> 0 | M7: =SUMIFS(LO!M:M,LO!$E:$E,$A7) -> 0 | N7: =L7/M7 -> #DIV/0! | O7: =SUMIFS(LO!O:O,LO!$E:$E,$A7) -> 0 | P7: =SUMIFS(LO!P:P,LO!$E:$E,$A7) -> 0 | Q7: =O7/P7 -> #DIV/0! | R7: =SUMIFS(LO!R:R,LO!$E:$E,$A7) -> 0 | S7: =SUMIFS(LO!S:S,LO!$E:$E,$A7) -> 0 | T7: =S7/R7 -> #DIV/0! | U7: =SUMIFS(LO!U:U,LO!$E:$E,$A7) -> 0 | V7: =(U7)/R7 -> #DIV/0! | W7: =SUMIFS(LO!W:W,LO!$E:$E,$A7) -> 0 | X7: =AVERAGEIFS(LO!X:X,LO!$E:$E,$A7) -> #DIV/0! | Y7: =SUMIFS(LO!Y:Y,LO!$E:$E,$A7) -> 0 | Z7: =Y7/$F7 -> #DIV/0! | AA7: =SUMIFS(LO!AA:AA,LO!$E:$E,$A7) -> 0 | AB7: =AA7/$F7 -> #DIV/0! | AD7: =MAX(0,MIN(AD$1,AD$1*(H7/(AD$2-AD$3)-(AD$3/(AD$2-AD$3))))) -> #DIV/0! | AE7: =MAX(0,MIN(AE$1,AE$1*(K7/(AE$2-AE$3)-(AE$3/(AE$2-AE$3))))) -> #DIV/0! | AF7: =MAX(0,MIN(AF$1,AF$1*(N7/(AF$2-AF$3)-(AF$3/(AF$2-AF$3))))) -> #DIV/0! | AG7: =MAX(0,MIN(AG$1,AG$1*(Q7/(AG$2-AG$3)-(AG$3/(AG$2-AG$3))))) -> #DIV/0! | AH7: =MIN(AH$1,MAX(0,AH$1-AH$1*(Z7/(AH$3-AH$2)-(AH$2/(AH$3-AH$2))))) -> #DIV/0! | AI7: =MIN(AI$1,MAX(0,AI$1-AI$1*(AB7/(AI$3-AI$2)-(AI$2/(AI$3-AI$2))))) -> #DIV/0! | AJ7: =MAX(0,MIN(AJ$1,AJ$1*(X7/(AJ$2-AJ$3)-(AJ$3/(AJ$2-AJ$3))))) -> #DIV/0! | AK7: =MAX(0,MIN(AK$1,AK$1*(T7/(AK$2-AK$3)-(AK$3/(AK$2-AK$3))))) -> #DIV/0! | AL7: =MAX(0,MIN(AL$1,AL$1*(V7/(AL$2-AL$3)-(AL$3/(AL$2-AL$3))))) -> #DIV/0! | AM7: =ROUND(SUM(AD7:AL7),0) -> #DIV/0! | AN7: 2573 | AO7: =ROUNDUP($AN7*AO$3,0) -> 1802 | AP7: =ROUNDDOWN($AN7*AP$3,0) -> 771 | AQ7: =MIN($AP7+$AQ$1,MAX($AP7+$AQ$2,MAX(0,$AP7/$AO$1*$AM7))) -> #DIV/0! | AR7: =AQ7+AO7 -> #DIV/0! | AS7: =AR7-AN7 -> #DIV/0! | AT7: =AR7/AN7 -> #DIV/0!
A8: Hayder Hashim Mohammed | D8: Dewaniya | E8: =COUNTIFS(LO!E:E,$A8) -> 26 | F8: =SUMIFS(LO!F:F,LO!$E:$E,$A8) -> 16394152 | G8: =SUMIFS(LO!G:G,LO!$E:$E,$A8) -> 10444444 | H8: =F8/G8 -> 1.5696528 | I8: =SUMIFS(LO!I:I,LO!$E:$E,$A8) -> 5818 | J8: =SUMIFS(LO!J:J,LO!$E:$E,$A8) -> 12356 | K8: =I8/J8 -> 0.47086436 | L8: =SUMIFS(LO!L:L,LO!$E:$E,$A8) -> 1394659.1 | M8: =SUMIFS(LO!M:M,LO!$E:$E,$A8) -> 1568181.8 | N8: =L8/M8 -> 0.88934786 | O8: =SUMIFS(LO!O:O,LO!$E:$E,$A8) -> 309 | P8: =SUMIFS(LO!P:P,LO!$E:$E,$A8) -> 362 | Q8: =O8/P8 -> 0.85359116 | R8: =SUMIFS(LO!R:R,LO!$E:$E,$A8) -> 307 | S8: =SUMIFS(LO!S:S,LO!$E:$E,$A8) -> 159 | T8: =S8/R8 -> 0.51791531 | U8: =SUMIFS(LO!U:U,LO!$E:$E,$A8) -> 170 | V8: =(U8)/R8 -> 0.55374593 | W8: =SUMIFS(LO!W:W,LO!$E:$E,$A8) -> 5818 | X8: =AVERAGEIFS(LO!X:X,LO!$E:$E,$A8) -> 0.89507692 | Y8: =SUMIFS(LO!Y:Y,LO!$E:$E,$A8) -> 377933.55 | Z8: =Y8/$F8 -> 0.023052949 | AA8: =SUMIFS(LO!AA:AA,LO!$E:$E,$A8) -> 287523.3 | AB8: =AA8/$F8 -> 0.017538162 | AD8: =MAX(0,MIN(AD$1,AD$1*(H8/(AD$2-AD$3)-(AD$3/(AD$2-AD$3))))) -> 10 | AE8: =MAX(0,MIN(AE$1,AE$1*(K8/(AE$2-AE$3)-(AE$3/(AE$2-AE$3))))) -> 0 | AF8: =MAX(0,MIN(AF$1,AF$1*(N8/(AF$2-AF$3)-(AF$3/(AF$2-AF$3))))) -> 15.778988 | AG8: =MAX(0,MIN(AG$1,AG$1*(Q8/(AG$2-AG$3)-(AG$3/(AG$2-AG$3))))) -> 0 | AH8: =MIN(AH$1,MAX(0,AH$1-AH$1*(Z8/(AH$3-AH$2)-(AH$2/(AH$3-AH$2))))) -> 14.084115 | AI8: =MIN(AI$1,MAX(0,AI$1-AI$1*(AB8/(AI$3-AI$2)-(AI$2/(AI$3-AI$2))))) -> 40 | AJ8: =MAX(0,MIN(AJ$1,AJ$1*(X8/(AJ$2-AJ$3)-(AJ$3/(AJ$2-AJ$3))))) -> 3.9507692 | AK8: =MAX(0,MIN(AK$1,AK$1*(T8/(AK$2-AK$3)-(AK$3/(AK$2-AK$3))))) -> 3.1791531 | AL8: =MAX(0,MIN(AL$1,AL$1*(V8/(AL$2-AL$3)-(AL$3/(AL$2-AL$3))))) -> 0 | AM8: =ROUND(SUM(AD8:AL8),0) -> 87 | AN8: 2141 | AO8: =ROUNDUP($AN8*AO$3,0) -> 1499 | AP8: =ROUNDDOWN($AN8*AP$3,0) -> 642 | AQ8: =MIN($AP8+$AQ$1,MAX($AP8+$AQ$2,MAX(0,$AP8/$AO$1*$AM8))) -> 642 | AR8: =AQ8+AO8 -> 2141 | AS8: =AR8-AN8 -> 0 | AT8: =AR8/AN8 -> 1
A9: Ammar Jawad hasan | D9: Dewaniya | E9: =COUNTIFS(LO!E:E,$A9) -> 10 | F9: =SUMIFS(LO!F:F,LO!$E:$E,$A9) -> 10193927 | G9: =SUMIFS(LO!G:G,LO!$E:$E,$A9) -> 19333333 | H9: =F9/G9 -> 0.52727206 | I9: =SUMIFS(LO!I:I,LO!$E:$E,$A9) -> 952 | J9: =SUMIFS(LO!J:J,LO!$E:$E,$A9) -> 2398 | K9: =I9/J9 -> 0.3969975 | L9: =SUMIFS(LO!L:L,LO!$E:$E,$A9) -> 566136.36 | M9: =SUMIFS(LO!M:M,LO!$E:$E,$A9) -> 909090.91 | N9: =L9/M9 -> 0.62275 | O9: =SUMIFS(LO!O:O,LO!$E:$E,$A9) -> 37 | P9: =SUMIFS(LO!P:P,LO!$E:$E,$A9) -> 42 | Q9: =O9/P9 -> 0.88095238 | R9: =SUMIFS(LO!R:R,LO!$E:$E,$A9) -> 37 | S9: =SUMIFS(LO!S:S,LO!$E:$E,$A9) -> 25 | T9: =S9/R9 -> 0.67567568 | U9: =SUMIFS(LO!U:U,LO!$E:$E,$A9) -> 16 | V9: =(U9)/R9 -> 0.43243243 | W9: =SUMIFS(LO!W:W,LO!$E:$E,$A9) -> 952 | X9: =AVERAGEIFS(LO!X:X,LO!$E:$E,$A9) -> 0.7942 | Y9: =SUMIFS(LO!Y:Y,LO!$E:$E,$A9) -> 251369.85 | Z9: =Y9/$F9 -> 0.024658786 | AA9: =SUMIFS(LO!AA:AA,LO!$E:$E,$A9) -> 292087.46 | AB9: =AA9/$F9 -> 0.028653086 | AD9: =MAX(0,MIN(AD$1,AD$1*(H9/(AD$2-AD$3)-(AD$3/(AD$2-AD$3))))) -> 0 | AE9: =MAX(0,MIN(AE$1,AE$1*(K9/(AE$2-AE$3)-(AE$3/(AE$2-AE$3))))) -> 0 | AF9: =MAX(0,MIN(AF$1,AF$1*(N9/(AF$2-AF$3)-(AF$3/(AF$2-AF$3))))) -> 0 | AG9: =MAX(0,MIN(AG$1,AG$1*(Q9/(AG$2-AG$3)-(AG$3/(AG$2-AG$3))))) -> 0 | AH9: =MIN(AH$1,MAX(0,AH$1-AH$1*(Z9/(AH$3-AH$2)-(AH$2/(AH$3-AH$2))))) -> 13.602364 | AI9: =MIN(AI$1,MAX(0,AI$1-AI$1*(AB9/(AI$3-AI$2)-(AI$2/(AI$3-AI$2))))) -> 40 | AJ9: =MAX(0,MIN(AJ$1,AJ$1*(X9/(AJ$2-AJ$3)-(AJ$3/(AJ$2-AJ$3))))) -> 2.942 | AK9: =MAX(0,MIN(AK$1,AK$1*(T9/(AK$2-AK$3)-(AK$3/(AK$2-AK$3))))) -> 4.7567568 | AL9: =MAX(0,MIN(AL$1,AL$1*(V9/(AL$2-AL$3)-(AL$3/(AL$2-AL$3))))) -> 0 | AM9: =ROUND(SUM(AD9:AL9),0) -> 61 | AN9: 2006 | AO9: =ROUNDUP($AN9*AO$3,0)+195 -> 1600 | AP9: =ROUNDDOWN($AN9*AP$3,0) -> 601 | AQ9: =MIN($AP9+$AQ$1,MAX($AP9+$AQ$2,MAX(0,$AP9/$AO$1*$AM9))) -> 601 | AR9: =AQ9+AO9 -> 2201 | AS9: =AR9-AN9 -> 195 | AT9: =AR9/AN9 -> 1.0972084
A10: Ezat Shamkhy Jaber | D10: Wehda | E10: =COUNTIFS(LO!E:E,$A10) -> 11 | F10: =SUMIFS(LO!F:F,LO!$E:$E,$A10) -> 6431720.3 | G10: =SUMIFS(LO!G:G,LO!$E:$E,$A10) -> 6777777.8 | H10: =F10/G10 -> 0.94894234 | I10: =SUMIFS(LO!I:I,LO!$E:$E,$A10) -> 1618 | J10: =SUMIFS(LO!J:J,LO!$E:$E,$A10) -> 7823 | K10: =I10/J10 -> 0.20682603 | L10: =SUMIFS(LO!L:L,LO!$E:$E,$A10) -> 443333.33 | M10: =SUMIFS(LO!M:M,LO!$E:$E,$A10) -> 784090.87 | N10: =L10/M10 -> 0.56541066 | O10: =SUMIFS(LO!O:O,LO!$E:$E,$A10) -> 75 | P10: =SUMIFS(LO!P:P,LO!$E:$E,$A10) -> 116 | Q10: =O10/P10 -> 0.64655172 | R10: =SUMIFS(LO!R:R,LO!$E:$E,$A10) -> 75 | S10: =SUMIFS(LO!S:S,LO!$E:$E,$A10) -> 42 | T10: =S10/R10 -> 0.56 | U10: =SUMIFS(LO!U:U,LO!$E:$E,$A10) -> 8 | V10: =(U10)/R10 -> 0.10666667 | W10: =SUMIFS(LO!W:W,LO!$E:$E,$A10) -> 1618 | X10: =AVERAGEIFS(LO!X:X,LO!$E:$E,$A10) -> 0.58836364 | Y10: =SUMIFS(LO!Y:Y,LO!$E:$E,$A10) -> 211587.02 | Z10: =Y10/$F10 -> 0.032897422 | AA10: =SUMIFS(LO!AA:AA,LO!$E:$E,$A10) -> 207759.33 | AB10: =AA10/$F10 -> 0.032302296 | AD10: =MAX(0,MIN(AD$1,AD$1*(H10/(AD$2-AD$3)-(AD$3/(AD$2-AD$3))))) -> 8.298078 | AE10: =MAX(0,MIN(AE$1,AE$1*(K10/(AE$2-AE$3)-(AE$3/(AE$2-AE$3))))) -> 0 | AF10: =MAX(0,MIN(AF$1,AF$1*(N10/(AF$2-AF$3)-(AF$3/(AF$2-AF$3))))) -> 0 | AG10: =MAX(0,MIN(AG$1,AG$1*(Q10/(AG$2-AG$3)-(AG$3/(AG$2-AG$3))))) -> 0 | AH10: =MIN(AH$1,MAX(0,AH$1-AH$1*(Z10/(AH$3-AH$2)-(AH$2/(AH$3-AH$2))))) -> 11.130773 | AI10: =MIN(AI$1,MAX(0,AI$1-AI$1*(AB10/(AI$3-AI$2)-(AI$2/(AI$3-AI$2))))) -> 40 | AJ10: =MAX(0,MIN(AJ$1,AJ$1*(X10/(AJ$2-AJ$3)-(AJ$3/(AJ$2-AJ$3))))) -> 0.88363636 | AK10: =MAX(0,MIN(AK$1,AK$1*(T10/(AK$2-AK$3)-(AK$3/(AK$2-AK$3))))) -> 3.6 | AL10: =MAX(0,MIN(AL$1,AL$1*(V10/(AL$2-AL$3)-(AL$3/(AL$2-AL$3))))) -> 0 | AM10: =ROUND(SUM(AD10:AL10),0) -> 64 | AN10: 2620 | AO10: =ROUNDUP($AN10*AO$3,0) -> 1834 | AP10: =ROUNDDOWN($AN10*AP$3,0) -> 786 | AQ10: =MIN($AP10+$AQ$1,MAX($AP10+$AQ$2,MAX(0,$AP10/$AO$1*$AM10))) -> 786 | AR10: =AQ10+AO10 -> 2620 | AS10: =AR10-AN10 -> 0 | AT10: =AR10/AN10 -> 1
A11: Alaa Kamil Qassim | D11: mansour | E11: =COUNTIFS(LO!E:E,$A11) -> 8 | F11: =SUMIFS(LO!F:F,LO!$E:$E,$A11) -> 4541722.7 | G11: =SUMIFS(LO!G:G,LO!$E:$E,$A11) -> 3555555.6 | H11: =F11/G11 -> 1.2773595 | I11: =SUMIFS(LO!I:I,LO!$E:$E,$A11) -> 1351 | J11: =SUMIFS(LO!J:J,LO!$E:$E,$A11) -> 4178 | K11: =I11/J11 -> 0.32336046 | L11: =SUMIFS(LO!L:L,LO!$E:$E,$A11) -> 323484.85 | M11: =SUMIFS(LO!M:M,LO!$E:$E,$A11) -> 499999.98 | N11: =L11/M11 -> 0.64696972 | O11: =SUMIFS(LO!O:O,LO!$E:$E,$A11) -> 63 | P11: =SUMIFS(LO!P:P,LO!$E:$E,$A11) -> 106 | Q11: =O11/P11 -> 0.59433962 | R11: =SUMIFS(LO!R:R,LO!$E:$E,$A11) -> 63 | S11: =SUMIFS(LO!S:S,LO!$E:$E,$A11) -> 37 | T11: =S11/R11 -> 0.58730159 | U11: =SUMIFS(LO!U:U,LO!$E:$E,$A11) -> 9 | V11: =(U11)/R11 -> 0.14285714 | W11: =SUMIFS(LO!W:W,LO!$E:$E,$A11) -> 1351 | X11: =AVERAGEIFS(LO!X:X,LO!$E:$E,$A11) -> 0.6755 | Y11: =SUMIFS(LO!Y:Y,LO!$E:$E,$A11) -> 89083.414 | Z11: =Y11/$F11 -> 0.019614455 | AA11: =SUMIFS(LO!AA:AA,LO!$E:$E,$A11) -> 97034.674 | AB11: =AA11/$F11 -> 0.021365169 | AD11: =MAX(0,MIN(AD$1,AD$1*(H11/(AD$2-AD$3)-(AD$3/(AD$2-AD$3))))) -> 10 | AE11: =MAX(0,MIN(AE$1,AE$1*(K11/(AE$2-AE$3)-(AE$3/(AE$2-AE$3))))) -> 0 | AF11: =MAX(0,MIN(AF$1,AF$1*(N11/(AF$2-AF$3)-(AF$3/(AF$2-AF$3))))) -> 0 | AG11: =MAX(0,MIN(AG$1,AG$1*(Q11/(AG$2-AG$3)-(AG$3/(AG$2-AG$3))))) -> 0 | AH11: =MIN(AH$1,MAX(0,AH$1-AH$1*(Z11/(AH$3-AH$2)-(AH$2/(AH$3-AH$2))))) -> 15 | AI11: =MIN(AI$1,MAX(0,AI$1-AI$1*(AB11/(AI$3-AI$2)-(AI$2/(AI$3-AI$2))))) -> 40 | AJ11: =MAX(0,MIN(AJ$1,AJ$1*(X11/(AJ$2-AJ$3)-(AJ$3/(AJ$2-AJ$3))))) -> 1.755 | AK11: =MAX(0,MIN(AK$1,AK$1*(T11/(AK$2-AK$3)-(AK$3/(AK$2-AK$3))))) -> 3.8730159 | AL11: =MAX(0,MIN(AL$1,AL$1*(V11/(AL$2-AL$3)-(AL$3/(AL$2-AL$3))))) -> 0 | AM11: =ROUND(SUM(AD11:AL11),0) -> 71 | AN11: 2111 | AO11: =ROUNDUP($AN11*AO$3,0) -> 1478 | AP11: =ROUNDDOWN($AN11*AP$3,0) -> 633 | AQ11: =MIN($AP11+$AQ$1,MAX($AP11+$AQ$2,MAX(0,$AP11/$AO$1*$AM11))) -> 633 | AR11: =AQ11+AO11 -> 2111 | AS11: =AR11-AN11 -> 0 | AT11: =AR11/AN11 -> 1
A12: Adel Hatef | E12: =COUNTIFS(LO!E:E,$A12) -> 7 | F12: =SUMIFS(LO!F:F,LO!$E:$E,$A12) -> 5005488.9 | G12: =SUMIFS(LO!G:G,LO!$E:$E,$A12) -> 4111111.1 | H12: =F12/G12 -> 1.2175513 | I12: =SUMIFS(LO!I:I,LO!$E:$E,$A12) -> 1304 | J12: =SUMIFS(LO!J:J,LO!$E:$E,$A12) -> 4756 | K12: =I12/J12 -> 0.27417998 | L12: =SUMIFS(LO!L:L,LO!$E:$E,$A12) -> 188446.97 | M12: =SUMIFS(LO!M:M,LO!$E:$E,$A12) -> 488636.34 | N12: =L12/M12 -> 0.38565893 | O12: =SUMIFS(LO!O:O,LO!$E:$E,$A12) -> 48 | P12: =SUMIFS(LO!P:P,LO!$E:$E,$A12) -> 77 | Q12: =O12/P12 -> 0.62337662 | R12: =SUMIFS(LO!R:R,LO!$E:$E,$A12) -> 48 | S12: =SUMIFS(LO!S:S,LO!$E:$E,$A12) -> 28 | T12: =S12/R12 -> 0.58333333 | U12: =SUMIFS(LO!U:U,LO!$E:$E,$A12) -> 32 | V12: =(U12)/R12 -> 0.66666667 | W12: =SUMIFS(LO!W:W,LO!$E:$E,$A12) -> 1304 | X12: =AVERAGEIFS(LO!X:X,LO!$E:$E,$A12) -> 0.74514286 | Y12: =SUMIFS(LO!Y:Y,LO!$E:$E,$A12) -> 182417.6 | Z12: =Y12/$F12 -> 0.036443513 | AA12: =SUMIFS(LO!AA:AA,LO!$E:$E,$A12) -> 298531.18 | AB12: =AA12/$F12 -> 0.059640763 | AD12: =MAX(0,MIN(AD$1,AD$1*(H12/(AD$2-AD$3)-(AD$3/(AD$2-AD$3))))) -> 10 | AE12: =MAX(0,MIN(AE$1,AE$1*(K12/(AE$2-AE$3)-(AE$3/(AE$2-AE$3))))) -> 0 | AF12: =MAX(0,MIN(AF$1,AF$1*(N12/(AF$2-AF$3)-(AF$3/(AF$2-AF$3))))) -> 0 | AG12: =MAX(0,MIN(AG$1,AG$1*(Q12/(AG$2-AG$3)-(AG$3/(AG$2-AG$3))))) -> 0 | AH12: =MIN(AH$1,MAX(0,AH$1-AH$1*(Z12/(AH$3-AH$2)-(AH$2/(AH$3-AH$2))))) -> 10.066946 | AI12: =MIN(AI$1,MAX(0,AI$1-AI$1*(AB12/(AI$3-AI$2)-(AI$2/(AI$3-AI$2))))) -> 36.143695 | AJ12: =MAX(0,MIN(AJ$1,AJ$1*(X12/(AJ$2-AJ$3)-(AJ$3/(AJ$2-AJ$3))))) -> 2.4514286 | AK12: =MAX(0,MIN(AK$1,AK$1*(T12/(AK$2-AK$3)-(AK$3/(AK$2-AK$3))))) -> 3.8333333 | AL12: =MAX(0,MIN(AL$1,AL$1*(V12/(AL$2-AL$3)-(AL$3/(AL$2-AL$3))))) -> 0 | AM12: =ROUND(SUM(AD12:AL12),0) -> 62 | AN12: 2296 | AO12: =ROUNDUP($AN12*AO$3,0) -> 1608 | AP12: =ROUNDDOWN($AN12*AP$3,0) -> 688 | AQ12: =MIN($AP12+$AQ$1,MAX($AP12+$AQ$2,MAX(0,$AP12/$AO$1*$AM12))) -> 688 | AR12: =AQ12+AO12 -> 2296 | AS12: =AR12-AN12 -> 0 | AT12: =AR12/AN12 -> 1
A13: Mustafa Sabeeh Hadi | D13: Hindiyah | E13: =COUNTIFS(LO!E:E,$A13) -> 33 | F13: =SUMIFS(LO!F:F,LO!$E:$E,$A13) -> 17361192 | G13: =SUMIFS(LO!G:G,LO!$E:$E,$A13) -> 16333333 | H13: =F13/G13 -> 1.0629301 | I13: =SUMIFS(LO!I:I,LO!$E:$E,$A13) -> 5329 | J13: =SUMIFS(LO!J:J,LO!$E:$E,$A13) -> 19068 | K13: =I13/J13 -> 0.27947346 | L13: =SUMIFS(LO!L:L,LO!$E:$E,$A13) -> 1359469.7 | M13: =SUMIFS(LO!M:M,LO!$E:$E,$A13) -> 2147727.2 | N13: =L13/M13 -> 0.63298063 | O13: =SUMIFS(LO!O:O,LO!$E:$E,$A13) -> 294 | P13: =SUMIFS(LO!P:P,LO!$E:$E,$A13) -> 411 | Q13: =O13/P13 -> 0.71532847 | R13: =SUMIFS(LO!R:R,LO!$E:$E,$A13) -> 294 | S13: =SUMIFS(LO!S:S,LO!$E:$E,$A13) -> 140 | T13: =S13/R13 -> 0.47619048 | U13: =SUMIFS(LO!U:U,LO!$E:$E,$A13) -> 114 | V13: =(U13)/R13 -> 0.3877551 | W13: =SUMIFS(LO!W:W,LO!$E:$E,$A13) -> 5329 | X13: =AVERAGEIFS(LO!X:X,LO!$E:$E,$A13) -> 0.64593939 | Y13: =SUMIFS(LO!Y:Y,LO!$E:$E,$A13) -> 540273.82 | Z13: =Y13/$F13 -> 0.031119627 | AA13: =SUMIFS(LO!AA:AA,LO!$E:$E,$A13) -> 249647.02 | AB13: =AA13/$F13 -> 0.014379601 | AD13: =MAX(0,MIN(AD$1,AD$1*(H13/(AD$2-AD$3)-(AD$3/(AD$2-AD$3))))) -> 10 | AE13: =MAX(0,MIN(AE$1,AE$1*(K13/(AE$2-AE$3)-(AE$3/(AE$2-AE$3))))) -> 0 | AF13: =MAX(0,MIN(AF$1,AF$1*(N13/(AF$2-AF$3)-(AF$3/(AF$2-AF$3))))) -> 0 | AG13: =MAX(0,MIN(AG$1,AG$1*(Q13/(AG$2-AG$3)-(AG$3/(AG$2-AG$3))))) -> 0 | AH13: =MIN(AH$1,MAX(0,AH$1-AH$1*(Z13/(AH$3-AH$2)-(AH$2/(AH$3-AH$2))))) -> 11.664112 | AI13: =MIN(AI$1,MAX(0,AI$1-AI$1*(AB13/(AI$3-AI$2)-(AI$2/(AI$3-AI$2))))) -> 40 | AJ13: =MAX(0,MIN(AJ$1,AJ$1*(X13/(AJ$2-AJ$3)-(AJ$3/(AJ$2-AJ$3))))) -> 1.4593939 | AK13: =MAX(0,MIN(AK$1,AK$1*(T13/(AK$2-AK$3)-(AK$3/(AK$2-AK$3))))) -> 2.7619048 | AL13: =MAX(0,MIN(AL$1,AL$1*(V13/(AL$2-AL$3)-(AL$3/(AL$2-AL$3))))) -> 0 | AM13: =ROUND(SUM(AD13:AL13),0) -> 66 | AN13: 2237 | AO13: =ROUNDUP($AN13*AO$3,0) -> 1566 | AP13: =ROUNDDOWN($AN13*AP$3,0) -> 671 | AQ13: =MIN($AP13+$AQ$1,MAX($AP13+$AQ$2,MAX(0,$AP13/$AO$1*$AM13))) -> 671 | AR13: =AQ13+AO13 -> 2237 | AS13: =AR13-AN13 -> 0 | AT13: =AR13/AN13 -> 1

Sheet LOS Incentive
A1: 1 | B1: 2 | C1: 3 | D1: 4 | E1: 5 | F1: 6 | G1: 7 | H1: 8 | I1: 9 | J1: 10 | K1: 11 | L1: 12 | M1: 13 | N1: 14 | O1: 15 | P1: 16 | Q1: 17 | R1: 18 | S1: 19 | T1: 20 | U1: 21 | V1: 22 | W1: 23 | X1: 24 | Y1: 25 | Z1: 26
B2: Micro | C2: =COUNTIFS(LO!B$7:B$288,$B2) -> 75 | E2: =LO!G5 -> 72000000 | H2: 32000 | N2: 2900 | U2: Actual | V2: Target | Z2: Weight | AA2: 0 | AB2: 0 | AC2: 30 | AD2: 0 | AE2: 20 | AF2: 40 | AG2: 0 | AH2: 5 | AI2: 5 | AJ2: =SUM(AC2:AI2) -> 100 | AK2: BenchMark | AL2: 50 | AN2: Maximum Increase | AO2: 300
B3: SE | C3: =COUNTIFS(LO!B$7:B$288,$B3) -> 9 | E3: Monthly Target | H3: Monthly Target | K3: Monthly Target | N3: Monthly Target | T3: Micro | U3: =AVERAGEIFS(LO!$W$7:$W$291,LO!$B$7:$B$291,$T3) -> 168.26667 | V3: 250 | W3: =SUBTOTAL(101,X$6:X$44) -> 0.025603636 | Y3: =SUBTOTAL(101,Z$6:Z$44) -> 0.022986133 | Z3: Max Input | AA3: 1 | AB3: 1 | AC3: 1 | AD3: 1 | AE3: 0.02 | AF3: 0.05 | AG3: 1 | AH3: 0.7 | AI3: 0.3 | AJ3: =AVERAGE(AJ6:AJ27) -> 74.181818 | AN3: Maximum Deducation | AO3: -400
C4: =SUBTOTAL(109,C$6:C$44) -> 120 | D4: =SUBTOTAL(109,D$6:D$44) -> 73211825 | E4: =SUBTOTAL(109,E$6:E$44) -> 72000000 | G4: =SUBTOTAL(109,G$6:G$44) -> 20184 | H4: =SUBTOTAL(109,H$6:H$44) -> 64002 | J4: =SUBTOTAL(109,J$6:J$44) -> 5604166.7 | K4: =SUBTOTAL(109,K6:K28) -> 7977272.4 | M4: =SUBTOTAL(109,M$6:M$44) -> 1094 | N4: =SUBTOTAL(109,N$6:N$44) -> 1440 | P4: =SUBTOTAL(109,P$6:P$44) -> 1092 | Q4: =SUBTOTAL(109,Q$6:Q$44) -> 556 | S4: =SUBTOTAL(109,S$6:S$44) -> 474 | T4: SE | U4: =AVERAGEIFS(LO!$W$7:$W$291,LO!$B$7:$B$291,$T4) -> 76.555556 | V4: 100 | W4: =SUBTOTAL(109,W$6:W$44) -> 1954070.2 | Y4: =SUBTOTAL(109,Y$6:Y$44) -> 1641872.7 | Z4: Min Input | AA4: 0.7 | AB4: 0.8 | AC4: 0.7 | AD4: 0.8 | AE4: 0.07 | AF4: 0.15 | AG4: 0.5 | AH4: 0.2 | AI4: 0 | AK4: =AK29 -> 36164 | AL4: 0.6 | AM4: 0.2 | AN4: =100%-AL4-AM4 -> 0.2 | AQ4: =AQ29 -> 3373.74
A5: Loan Officer Supervisor | B5: Branch | C5: Number of Staff. | D5: Actual Portfolio | E5: Target Portfolio | F5: Actual/Target | G5: Actual Active Clients | H5: Target Active Clients | I5: Actual/Target | J5: Actual Disbursement $ | K5: Tatget Disbursement $ | L5: Actual/Target | M5: Actual Disbursement # | N5: Tatget Disbursement # | O5: Actual/Target | P5: Disb Clients No. | Q5: Disb ReNew No. Clients | R5: Disb Renewal Rate (%) | S5: Disb Female No. Clients | T5: Disb Female Rate (%) | U5: Active Clients | V5: Case Load by LO | W5: PAR $ 0-30 | X5: PAR 0-30 | Y5: PAR $ >30 | Z5: PAR >30 | AA5: Portfolio Share | AB5: Active Clients Share | AC5: Disbursement $ Share | AD5: Disbursement # Portion | AE5: PAR 1-30 | AF5: PAR >30 | AG5: Case Load | AH5: Renewal Rate | AI5: Female Rate | AJ5: Total | AK5: Salaries | AL5: Contract | AM5: Fix | AN5: Net | AO5: Proposal Incentive | AP5: Proposal Total Salary | AQ5: Difference | AR5: New/Old Salary
A6: Ali Kadhum Wshah | B6: =VLOOKUP($A6,MainData!$C:$E,2,FALSE) -> Basra | C6: =COUNTIFS(LO!C:C,$A6) -> 5 | D6: =SUMIFS(LO!F:F,LO!$C:$C,$A6) -> 3853073.8 | E6: =SUMIFS(LO!G:G,LO!$C:$C,$A6) -> 4777777.8 | F6: =D6/E6 -> 0.8064573 | G6: =SUMIFS(LO!I:I,LO!$C:$C,$A6) -> 834 | H6: =SUMIFS(LO!J:J,LO!$C:$C,$A6) -> 3289 | I6: =G6/H6 -> 0.25357251 | J6: =SUMIFS(LO!L:L,LO!$C:$C,$A6) -> 286742.42 | K6: =SUMIFS(LO!M:M,LO!$C:$C,$A6) -> 390151.5 | L6: =J6/K6 -> 0.73495148 | M6: =SUMIFS(LO!O:O,LO!$C:$C,$A6) -> 51 | N6: =SUMIFS(LO!P:P,LO!$C:$C,$A6) -> 42 | O6: =M6/N6 -> 1.2142857 | P6: =SUMIFS(LO!R:R,LO!$C:$C,$A6) -> 51 | Q6: =SUMIFS(LO!S:S,LO!$C:$C,$A6) -> 24 | R6: =IFERROR(Q6/P6,0) -> 0.47058824 | S6: =SUMIFS(LO!U:U,LO!$C:$C,$A6) -> 22 | T6: =IFERROR((S6)/P6,0) -> 0.43137255 | U6: =SUMIFS(LO!W:W,LO!$C:$C,$A6) -> 834 | V6: =AVERAGEIFS(LO!X:X,LO!$C:$C,$A6) -> 0.7224 | W6: =SUMIFS(LO!Y:Y,LO!$C:$C,$A6) -> 84724.716 | X6: =W6/$D6 -> 0.021988864 | Y6: =SUMIFS(LO!AA:AA,LO!$C:$C,$A6) -> 171180.19 | Z6: =Y6/$D6 -> 0.044426918 | AC6: =MAX(0,MIN(AC$2,AC$2*(L6/(AC$3-AC$4)-(AC$4/(AC$3-AC$4))))) -> 3.4951485 | AD6: =MAX(0,MIN(AD$2,AD$2*(O6/(AD$3-AD$4)-(AD$4/(AD$3-AD$4))))) -> 0 | AE6: =MIN(AE$2,MAX(0,AE$2-AE$2*(X6/(AE$4-AE$3)-(AE$3/(AE$4-AE$3))))) -> 19.204454 | AF6: =MIN(AF$2,MAX(0,AF$2-AF$2*(Z6/(AF$4-AF$3)-(AF$3/(AF$4-AF$3))))) -> 40 | AG6: =MAX(0,MIN(AG$2,AG$2*(V6/(AG$3-AG$4)-(AG$4/(AG$3-AG$4))))) -> 0 | AH6: =MAX(0,MIN(AH$2,AH$2*(R6/(AH$3-AH$4)-(AH$4/(AH$3-AH$4))))) -> 2.7058824 | AI6: =MAX(0,MIN(AI$2,AI$2*(T6/(AI$3-AI$4)-(AI$4/(AI$3-AI$4))))) -> 5 | AJ6: =ROUND(SUM(AC6:AI6),0) -> 70 | AK6: 1040 | AL6: =ROUNDUP($AK6*AL$4,0) -> 624 | AM6: =ROUNDDOWN($AK6*AM$4,0) -> 208 | AN6: =ROUNDDOWN($AK6*AN$4,0) -> 208 | AO6: =MIN($AN6+$AO$2,MAX($AN6+$AO$3,MAX(0,$AN6/$AL$2*$AJ6))) -> 291.2 | AP6: =AO6+AL6+AM6 -> 1123.2 | AQ6: =AP6-AK6 -> 83.2 | AR6: =AP6/AK6 -> 1.08
A7: Dhea Ghani Mohammad | B7: =VLOOKUP($A7,MainData!$C:$E,2,FALSE) -> Hashimiyah | C7: =COUNTIFS(LO!C:C,$A7) -> 4 | D7: =SUMIFS(LO!F:F,LO!$C:$C,$A7) -> 2812111 | E7: =SUMIFS(LO!G:G,LO!$C:$C,$A7) -> 1333333.3 | F7: =D7/E7 -> 2.1090832 | G7: =SUMIFS(LO!I:I,LO!$C:$C,$A7) -> 943 | H7: =SUMIFS(LO!J:J,LO!$C:$C,$A7) -> 1600 | I7: =G7/H7 -> 0.589375 | J7: =SUMIFS(LO!L:L,LO!$C:$C,$A7) -> 245454.55 | K7: =SUMIFS(LO!M:M,LO!$C:$C,$A7) -> 227272.72 | L7: =J7/K7 -> 1.08 | M7: =SUMIFS(LO!O:O,LO!$C:$C,$A7) -> 53 | N7: =SUMIFS(LO!P:P,LO!$C:$C,$A7) -> 60 | O7: =M7/N7 -> 0.88333333 | P7: =SUMIFS(LO!R:R,LO!$C:$C,$A7) -> 53 | Q7: =SUMIFS(LO!S:S,LO!$C:$C,$A7) -> 25 | R7: =IFERROR(Q7/P7,0) -> 0.47169811 | S7: =SUMIFS(LO!U:U,LO!$C:$C,$A7) -> 21 | T7: =IFERROR((S7)/P7,0) -> 0.39622642 | U7: =SUMIFS(LO!W:W,LO!$C:$C,$A7) -> 943 | V7: =AVERAGEIFS(LO!X:X,LO!$C:$C,$A7) -> 0.943 | W7: =SUMIFS(LO!Y:Y,LO!$C:$C,$A7) -> 23790.535 | X7: =W7/$D7 -> 0.0084600272 | Y7: =SUMIFS(LO!AA:AA,LO!$C:$C,$A7) -> 19164.651 | Z7: =Y7/$D7 -> 0.0068150409 | AC7: =MAX(0,MIN(AC$2,AC$2*(L7/(AC$3-AC$4)-(AC$4/(AC$3-AC$4))))) -> 30 | AD7: =MAX(0,MIN(AD$2,AD$2*(O7/(AD$3-AD$4)-(AD$4/(AD$3-AD$4))))) -> 0 | AE7: =MIN(AE$2,MAX(0,AE$2-AE$2*(X7/(AE$4-AE$3)-(AE$3/(AE$4-AE$3))))) -> 20 | AF7: =MIN(AF$2,MAX(0,AF$2-AF$2*(Z7/(AF$4-AF$3)-(AF$3/(AF$4-AF$3))))) -> 40 | AG7: =MAX(0,MIN(AG$2,AG$2*(V7/(AG$3-AG$4)-(AG$4/(AG$3-AG$4))))) -> 0 | AH7: =MAX(0,MIN(AH$2,AH$2*(R7/(AH$3-AH$4)-(AH$4/(AH$3-AH$4))))) -> 2.7169811 | AI7: =MAX(0,MIN(AI$2,AI$2*(T7/(AI$3-AI$4)-(AI$4/(AI$3-AI$4))))) -> 5 | AJ7: =ROUND(SUM(AC7:AI7),0) -> 98 | AK7: 1411 | AL7: =ROUNDUP($AK7*AL$4,0) -> 847 | AM7: =ROUNDDOWN($AK7*AM$4,0) -> 282 | AN7: =ROUNDDOWN($AK7*AN$4,0) -> 282 | AO7: =MIN($AN7+$AO$2,MAX($AN7+$AO$3,MAX(0,$AN7/$AL$2*$AJ7))) -> 552.72 | AP7: =AO7+AL7+AM7 -> 1681.72 | AQ7: =AP7-AK7 -> 270.72 | AR7: =AP7/AK7 -> 1.1918639
A8: Amer Ahmed AbdulWahid | B8: =VLOOKUP($A8,MainData!$C:$E,2,FALSE) -> Dewaniya | C8: =COUNTIFS(LO!C:C,$A8) -> 5 | D8: =SUMIFS(LO!F:F,LO!$C:$C,$A8) -> 3242751.5 | E8: =SUMIFS(LO!G:G,LO!$C:$C,$A8) -> 2555555.6 | F8: =D8/E8 -> 1.2689027 | G8: =SUMIFS(LO!I:I,LO!$C:$C,$A8) -> 794 | H8: =SUMIFS(LO!J:J,LO!$C:$C,$A8) -> 2978 | I8: =G8/H8 -> 0.26662189 | J8: =SUMIFS(LO!L:L,LO!$C:$C,$A8) -> 320227.27 | K8: =SUMIFS(LO!M:M,LO!$C:$C,$A8) -> 329545.44 | L8: =J8/K8 -> 0.97172418 | M8: =SUMIFS(LO!O:O,LO!$C:$C,$A8) -> 59 | N8: =SUMIFS(LO!P:P,LO!$C:$C,$A8) -> 61 | O8: =M8/N8 -> 0.96721311 | P8: =SUMIFS(LO!R:R,LO!$C:$C,$A8) -> 57 | Q8: =SUMIFS(LO!S:S,LO!$C:$C,$A8) -> 37 | R8: =IFERROR(Q8/P8,0) -> 0.64912281 | S8: =SUMIFS(LO!U:U,LO!$C:$C,$A8) -> 20 | T8: =IFERROR((S8)/P8,0) -> 0.35087719 | U8: =SUMIFS(LO!W:W,LO!$C:$C,$A8) -> 794 | V8: =AVERAGEIFS(LO!X:X,LO!$C:$C,$A8) -> 0.6352 | W8: =SUMIFS(LO!Y:Y,LO!$C:$C,$A8) -> 100170.17 | X8: =W8/$D8 -> 0.030890486 | Y8: =SUMIFS(LO!AA:AA,LO!$C:$C,$A8) -> 78300.407 | Z8: =Y8/$D8 -> 0.024146287 | AC8: =MAX(0,MIN(AC$2,AC$2*(L8/(AC$3-AC$4)-(AC$4/(AC$3-AC$4))))) -> 27.172418 | AD8: =MAX(0,MIN(AD$2,AD$2*(O8/(AD$3-AD$4)-(AD$4/(AD$3-AD$4))))) -> 0 | AE8: =MIN(AE$2,MAX(0,AE$2-AE$2*(X8/(AE$4-AE$3)-(AE$3/(AE$4-AE$3))))) -> 15.643806 | AF8: =MIN(AF$2,MAX(0,AF$2-AF$2*(Z8/(AF$4-AF$3)-(AF$3/(AF$4-AF$3))))) -> 40 | AG8: =MAX(0,MIN(AG$2,AG$2*(V8/(AG$3-AG$4)-(AG$4/(AG$3-AG$4))))) -> 0 | AH8: =MAX(0,MIN(AH$2,AH$2*(R8/(AH$3-AH$4)-(AH$4/(AH$3-AH$4))))) -> 4.4912281 | AI8: =MAX(0,MIN(AI$2,AI$2*(T8/(AI$3-AI$4)-(AI$4/(AI$3-AI$4))))) -> 5 | AJ8: =ROUND(SUM(AC8:AI8),0) -> 92 | AK8: 1411 | AL8: =ROUNDUP($AK8*AL$4,0) -> 847 | AM8: =ROUNDDOWN($AK8*AM$4,0) -> 282 | AN8: =ROUNDDOWN($AK8*AN$4,0) -> 282 | AO8: =MIN($AN8+$AO$2,MAX($AN8+$AO$3,MAX(0,$AN8/$AL$2*$AJ8))) -> 518.88 | AP8: =AO8+AL8+AM8 -> 1647.88 | AQ8: =AP8-AK8 -> 236.88 | AR8: =AP8/AK8 -> 1.1678809
A9: Hayder Hussein Obayes | B9: =VLOOKUP($A9,MainData!$C:$E,2,FALSE) -> Hashimiyah | C9: =COUNTIFS(LO!C:C,$A9) -> 4 | D9: =SUMIFS(LO!F:F,LO!$C:$C,$A9) -> 2445334.1 | E9: =SUMIFS(LO!G:G,LO!$C:$C,$A9) -> 3111111.1 | F9: =D9/E9 -> 0.78600026 | G9: =SUMIFS(LO!I:I,LO!$C:$C,$A9) -> 636 | H9: =SUMIFS(LO!J:J,LO!$C:$C,$A9) -> 1422 | I9: =G9/H9 -> 0.44725738 | J9: =SUMIFS(LO!L:L,LO!$C:$C,$A9) -> 263560.61 | K9: =SUMIFS(LO!M:M,LO!$C:$C,$A9) -> 265151.51 | L9: =J9/K9 -> 0.99400002 | M9: =SUMIFS(LO!O:O,LO!$C:$C,$A9) -> 48 | N9: =SUMIFS(LO!P:P,LO!$C:$C,$A9) -> 48 | O9: =M9/N9 -> 1 | P9: =SUMIFS(LO!R:R,LO!$C:$C,$A9) -> 48 | Q9: =SUMIFS(LO!S:S,LO!$C:$C,$A9) -> 27 | R9: =IFERROR(Q9/P9,0) -> 0.5625 | S9: =SUMIFS(LO!U:U,LO!$C:$C,$A9) -> 24 | T9: =IFERROR((S9)/P9,0) -> 0.5 | U9: =SUMIFS(LO!W:W,LO!$C:$C,$A9) -> 636 | V9: =AVERAGEIFS(LO!X:X,LO!$C:$C,$A9) -> 0.7605 | W9: =SUMIFS(LO!Y:Y,LO!$C:$C,$A9) -> 14831.416 | X9: =W9/$D9 -> 0.0060651898 | Y9: =SUMIFS(LO!AA:AA,LO!$C:$C,$A9) -> 8242.8173 | Z9: =Y9/$D9 -> 0.0033708347 | AC9: =MAX(0,MIN(AC$2,AC$2*(L9/(AC$3-AC$4)-(AC$4/(AC$3-AC$4))))) -> 29.400002 | AD9: =MAX(0,MIN(AD$2,AD$2*(O9/(AD$3-AD$4)-(AD$4/(AD$3-AD$4))))) -> 0 | AE9: =MIN(AE$2,MAX(0,AE$2-AE$2*(X9/(AE$4-AE$3)-(AE$3/(AE$4-AE$3))))) -> 20 | AF9: =MIN(AF$2,MAX(0,AF$2-AF$2*(Z9/(AF$4-AF$3)-(AF$3/(AF$4-AF$3))))) -> 40 | AG9: =MAX(0,MIN(AG$2,AG$2*(V9/(AG$3-AG$4)-(AG$4/(AG$3-AG$4))))) -> 0 | AH9: =MAX(0,MIN(AH$2,AH$2*(R9/(AH$3-AH$4)-(AH$4/(AH$3-AH$4))))) -> 3.625 | AI9: =MAX(0,MIN(AI$2,AI$2*(T9/(AI$3-AI$4)-(AI$4/(AI$3-AI$4))))) -> 5 | AJ9: =ROUND(SUM(AC9:AI9),0) -> 98 | AK9: 1962 | AL9: =ROUNDUP($AK9*AL$4,0) -> 1178 | AM9: =ROUNDDOWN($AK9*AM$4,0) -> 392 | AN9: =ROUNDDOWN($AK9*AN$4,0) -> 392 | AO9: =MIN($AN9+$AO$2,MAX($AN9+$AO$3,MAX(0,$AN9/$AL$2*$AJ9))) -> 692 | AP9: =AO9+AL9+AM9 -> 2262 | AQ9: =AP9-AK9 -> 300 | AR9: =AP9/AK9 -> 1.1529052
A10: Hasanain Kadhum Abed | B10: =VLOOKUP($A10,MainData!$C:$E,2,FALSE) -> Hilla | C10: =COUNTIFS(LO!C:C,$A10) -> 10 | D10: =SUMIFS(LO!F:F,LO!$C:$C,$A10) -> 4612674.4 | E10: =SUMIFS(LO!G:G,LO!$C:$C,$A10) -> 6444444.4 | F10: =D10/E10 -> 0.71575981 | G10: =SUMIFS(LO!I:I,LO!$C:$C,$A10) -> 945 | H10: =SUMIFS(LO!J:J,LO!$C:$C,$A10) -> 5289 | I10: =G10/H10 -> 0.17867272 | J10: =SUMIFS(LO!L:L,LO!$C:$C,$A10) -> 292575.76 | K10: =SUMIFS(LO!M:M,LO!$C:$C,$A10) -> 674242.4 | L10: =J10/K10 -> 0.4339326 | M10: =SUMIFS(LO!O:O,LO!$C:$C,$A10) -> 52 | N10: =SUMIFS(LO!P:P,LO!$C:$C,$A10) -> 117 | O10: =M10/N10 -> 0.44444444 | P10: =SUMIFS(LO!R:R,LO!$C:$C,$A10) -> 52 | Q10: =SUMIFS(LO!S:S,LO!$C:$C,$A10) -> 22 | R10: =IFERROR(Q10/P10,0) -> 0.42307692 | S10: =SUMIFS(LO!U:U,LO!$C:$C,$A10) -> 17 | T10: =IFERROR((S10)/P10,0) -> 0.32692308 | U10: =SUMIFS(LO!W:W,LO!$C:$C,$A10) -> 945 | V10: =AVERAGEIFS(LO!X:X,LO!$C:$C,$A10) -> 0.4218 | W10: =SUMIFS(LO!Y:Y,LO!$C:$C,$A10) -> 104435.96 | X10: =W10/$D10 -> 0.022641086 | Y10: =SUMIFS(LO!AA:AA,LO!$C:$C,$A10) -> 148572.2 | Z10: =Y10/$D10 -> 0.032209557 | AC10: =MAX(0,MIN(AC$2,AC$2*(L10/(AC$3-AC$4)-(AC$4/(AC$3-AC$4))))) -> 0 | AD10: =MAX(0,MIN(AD$2,AD$2*(O10/(AD$3-AD$4)-(AD$4/(AD$3-AD$4))))) -> 0 | AE10: =MIN(AE$2,MAX(0,AE$2-AE$2*(X10/(AE$4-AE$3)-(AE$3/(AE$4-AE$3))))) -> 18.943566 | AF10: =MIN(AF$2,MAX(0,AF$2-AF$2*(Z10/(AF$4-AF$3)-(AF$3/(AF$4-AF$3))))) -> 40 | AG10: =MAX(0,MIN(AG$2,AG$2*(V10/(AG$3-AG$4)-(AG$4/(AG$3-AG$4))))) -> 0 | AH10: =MAX(0,MIN(AH$2,AH$2*(R10/(AH$3-AH$4)-(AH$4/(AH$3-AH$4))))) -> 2.2307692 | AI10: =MAX(0,MIN(AI$2,AI$2*(T10/(AI$3-AI$4)-(AI$4/(AI$3-AI$4))))) -> 5 | AJ10: =ROUND(SUM(AC10:AI10),0) -> 66 | AK10: 1623 | AL10: =ROUNDUP($AK10*AL$4,0) -> 974 | AM10: =ROUNDDOWN($AK10*AM$4,0) -> 324 | AN10: =ROUNDDOWN($AK10*AN$4,0) -> 324 | AO10: =MIN($AN10+$AO$2,MAX($AN10+$AO$3,MAX(0,$AN10/$AL$2*$AJ10))) -> 427.68 | AP10: =AO10+AL10+AM10 -> 1725.68 | AQ10: =AP10-AK10 -> 102.68 | AR10: =AP10/AK10 -> 1.0632656
A11: Muhammad Qahtan Mindeel | B11: =VLOOKUP($A11,MainData!$C:$E,2,FALSE) -> Hilla | C11: =COUNTIFS(LO!C:C,$A11) -> 9 | D11: =SUMIFS(LO!F:F,LO!$C:$C,$A11) -> 4684525.5 | E11: =SUMIFS(LO!G:G,LO!$C:$C,$A11) -> 4777777.8 | F11: =D11/E11 -> 0.98048207 | G11: =SUMIFS(LO!I:I,LO!$C:$C,$A11) -> 1269 | H11: =SUMIFS(LO!J:J,LO!$C:$C,$A11) -> 5556 | I11: =G11/H11 -> 0.22840173 | J11: =SUMIFS(LO!L:L,LO!$C:$C,$A11) -> 283636.36 | K11: =SUMIFS(LO!M:M,LO!$C:$C,$A11) -> 602272.7 | L11: =J11/K11 -> 0.47094342 | M11: =SUMIFS(LO!O:O,LO!$C:$C,$A11) -> 60 | N11: =SUMIFS(LO!P:P,LO!$C:$C,$A11) -> 107 | O11: =M11/N11 -> 0.56074766 | P11: =SUMIFS(LO!R:R,LO!$C:$C,$A11) -> 60 | Q11: =SUMIFS(LO!S:S,LO!$C:$C,$A11) -> 24 | R11: =IFERROR(Q11/P11,0) -> 0.4 | S11: =SUMIFS(LO!U:U,LO!$C:$C,$A11) -> 29 | T11: =IFERROR((S11)/P11,0) -> 0.48333333 | U11: =SUMIFS(LO!W:W,LO!$C:$C,$A11) -> 1269 | V11: =AVERAGEIFS(LO!X:X,LO!$C:$C,$A11) -> 0.564 | W11: =SUMIFS(LO!Y:Y,LO!$C:$C,$A11) -> 87511.929 | X11: =W11/$D11 -> 0.018681066 | Y11: =SUMIFS(LO!AA:AA,LO!$C:$C,$A11) -> 99803.87 | Z11: =Y11/$D11 -> 0.021305012 | AC11: =MAX(0,MIN(AC$2,AC$2*(L11/(AC$3-AC$4)-(AC$4/(AC$3-AC$4))))) -> 0 | AD11: =MAX(0,MIN(AD$2,AD$2*(O11/(AD$3-AD$4)-(AD$4/(AD$3-AD$4))))) -> 0 | AE11: =MIN(AE$2,MAX(0,AE$2-AE$2*(X11/(AE$4-AE$3)-(AE$3/(AE$4-AE$3))))) -> 20 | AF11: =MIN(AF$2,MAX(0,AF$2-AF$2*(Z11/(AF$4-AF$3)-(AF$3/(AF$4-AF$3))))) -> 40 | AG11: =MAX(0,MIN(AG$2,AG$2*(V11/(AG$3-AG$4)-(AG$4/(AG$3-AG$4))))) -> 0 | AH11: =MAX(0,MIN(AH$2,AH$2*(R11/(AH$3-AH$4)-(AH$4/(AH$3-AH$4))))) -> 2 | AI11: =MAX(0,MIN(AI$2,AI$2*(T11/(AI$3-AI$4)-(AI$4/(AI$3-AI$4))))) -> 5 | AJ11: =ROUND(SUM(AC11:AI11),0) -> 67 | AK11: 1621 | AL11: =ROUNDUP($AK11*AL$4,0) -> 973 | AM11: =ROUNDDOWN($AK11*AM$4,0) -> 324 | AN11: =ROUNDDOWN($AK11*AN$4,0) -> 324 | AO11: =MIN($AN11+$AO$2,MAX($AN11+$AO$3,MAX(0,$AN11/$AL$2*$AJ11))) -> 434.16 | AP11: =AO11+AL11+AM11 -> 1731.16 | AQ11: =AP11-AK11 -> 110.16 | AR11: =AP11/AK11 -> 1.0679581
A12: Yais Khdhir Dikhi | B12: =VLOOKUP($A12,MainData!$C:$E,2,FALSE) -> Hindiyah | C12: =COUNTIFS(LO!C:C,$A12) -> 5 | D12: =SUMIFS(LO!F:F,LO!$C:$C,$A12) -> 3037659.1 | E12: =SUMIFS(LO!G:G,LO!$C:$C,$A12) -> 1666666.7 | F12: =D12/E12 -> 1.8225955 | G12: =SUMIFS(LO!I:I,LO!$C:$C,$A12) -> 1133 | H12: =SUMIFS(LO!J:J,LO!$C:$C,$A12) -> 2000 | I12: =G12/H12 -> 0.5665 | J12: =SUMIFS(LO!L:L,LO!$C:$C,$A12) -> 283333.33 | K12: =SUMIFS(LO!M:M,LO!$C:$C,$A12) -> 284090.9 | L12: =J12/K12 -> 0.99733337 | M12: =SUMIFS(LO!O:O,LO!$C:$C,$A12) -> 74 | N12: =SUMIFS(LO!P:P,LO!$C:$C,$A12) -> 75 | O12: =M12/N12 -> 0.98666667 | P12: =SUMIFS(LO!R:R,LO!$C:$C,$A12) -> 74 | Q12: =SUMIFS(LO!S:S,LO!$C:$C,$A12) -> 38 | R12: =IFERROR(Q12/P12,0) -> 0.51351351 | S12: =SUMIFS(LO!U:U,LO!$C:$C,$A12) -> 31 | T12: =IFERROR((S12)/P12,0) -> 0.41891892 | U12: =SUMIFS(LO!W:W,LO!$C:$C,$A12) -> 1133 | V12: =AVERAGEIFS(LO!X:X,LO!$C:$C,$A12) -> 0.9064 | W12: =SUMIFS(LO!Y:Y,LO!$C:$C,$A12) -> 1345.6194 | X12: =W12/$D12 -> 0.00044297906 | Y12: =SUMIFS(LO!AA:AA,LO!$C:$C,$A12) -> 0 | Z12: =Y12/$D12 -> 0 | AC12: =MAX(0,MIN(AC$2,AC$2*(L12/(AC$3-AC$4)-(AC$4/(AC$3-AC$4))))) -> 29.733337 | AD12: =MAX(0,MIN(AD$2,AD$2*(O12/(AD$3-AD$4)-(AD$4/(AD$3-AD$4))))) -> 0 | AE12: =MIN(AE$2,MAX(0,AE$2-AE$2*(X12/(AE$4-AE$3)-(AE$3/(AE$4-AE$3))))) -> 20 | AF12: =MIN(AF$2,MAX(0,AF$2-AF$2*(Z12/(AF$4-AF$3)-(AF$3/(AF$4-AF$3))))) -> 40 | AG12: =MAX(0,MIN(AG$2,AG$2*(V12/(AG$3-AG$4)-(AG$4/(AG$3-AG$4))))) -> 0 | AH12: =MAX(0,MIN(AH$2,AH$2*(R12/(AH$3-AH$4)-(AH$4/(AH$3-AH$4))))) -> 3.1351351 | AI12: =MAX(0,MIN(AI$2,AI$2*(T12/(AI$3-AI$4)-(AI$4/(AI$3-AI$4))))) -> 5 | AJ12: =ROUND(SUM(AC12:AI12),0) -> 98 | AK12: 1387 | AL12: =ROUNDUP($AK12*AL$4,0) -> 833 | AM12: =ROUNDDOWN($AK12*AM$4,0) -> 277 | AN12: =ROUNDDOWN($AK12*AN$4,0) -> 277 | AO12: =MIN($AN12+$AO$2,MAX($AN12+$AO$3,MAX(0,$AN12/$AL$2*$AJ12))) -> 542.92 | AP12: =AO12+AL12+AM12 -> 1652.92 | AQ12: =AP12-AK12 -> 265.92 | AR12: =AP12/AK12 -> 1.1917231
A13: Ali Manji Oafi | B13: =VLOOKUP($A13,MainData!$C:$E,2,FALSE) -> Karbala | C13: =COUNTIFS(LO!C:C,$A13) -> 5 | D13: =SUMIFS(LO!F:F,LO!$C:$C,$A13) -> 3508593 | E13: =SUMIFS(LO!G:G,LO!$C:$C,$A13) -> 3000000 | F13: =D13/E13 -> 1.169531 | G13: =SUMIFS(LO!I:I,LO!$C:$C,$A13) -> 1056 | H13: =SUMIFS(LO!J:J,LO!$C:$C,$A13) -> 3467 | I13: =G13/H13 -> 0.3045861 | J13: =SUMIFS(LO!L:L,LO!$C:$C,$A13) -> 318181.82 | K13: =SUMIFS(LO!M:M,LO!$C:$C,$A13) -> 352272.71 | L13: =J13/K13 -> 0.90322585 | M13: =SUMIFS(LO!O:O,LO!$C:$C,$A13) -> 65 | N13: =SUMIFS(LO!P:P,LO!$C:$C,$A13) -> 54 | O13: =M13/N13 -> 1.2037037 | P13: =SUMIFS(LO!R:R,LO!$C:$C,$A13) -> 65 | Q13: =SUMIFS(LO!S:S,LO!$C:$C,$A13) -> 34 | R13: =IFERROR(Q13/P13,0) -> 0.52307692 | S13: =SUMIFS(LO!U:U,LO!$C:$C,$A13) -> 24 | T13: =IFERROR((S13)/P13,0) -> 0.36923077 | U13: =SUMIFS(LO!W:W,LO!$C:$C,$A13) -> 1056 | V13: =AVERAGEIFS(LO!X:X,LO!$C:$C,$A13) -> 0.8448 | W13: =SUMIFS(LO!Y:Y,LO!$C:$C,$A13) -> 271387.09 | X13: =W13/$D13 -> 0.077349267 | Y13: =SUMIFS(LO!AA:AA,LO!$C:$C,$A13) -> 49472.218 | Z13: =Y13/$D13 -> 0.014100301 | AC13: =MAX(0,MIN(AC$2,AC$2*(L13/(AC$3-AC$4)-(AC$4/(AC$3-AC$4))))) -> 20.322585 | AD13: =MAX(0,MIN(AD$2,AD$2*(O13/(AD$3-AD$4)-(AD$4/(AD$3-AD$4))))) -> 0 | AE13: =MIN(AE$2,MAX(0,AE$2-AE$2*(X13/(AE$4-AE$3)-(AE$3/(AE$4-AE$3))))) -> 0 | AF13: =MIN(AF$2,MAX(0,AF$2-AF$2*(Z13/(AF$4-AF$3)-(AF$3/(AF$4-AF$3))))) -> 40 | AG13: =MAX(0,MIN(AG$2,AG$2*(V13/(AG$3-AG$4)-(AG$4/(AG$3-AG$4))))) -> 0 | AH13: =MAX(0,MIN(AH$2,AH$2*(R13/(AH$3-AH$4)-(AH$4/(AH$3-AH$4))))) -> 3.2307692 | AI13: =MAX(0,MIN(AI$2,AI$2*(T13/(AI$3-AI$4)-(AI$4/(AI$3-AI$4))))) -> 5 | AJ13: =ROUND(SUM(AC13:AI13),0) -> 69 | AK13: 1621 | AL13: =ROUNDUP($AK13*AL$4,0) -> 973 | AM13: =ROUNDDOWN($AK13*AM$4,0) -> 324 | AN13: =ROUNDDOWN($AK13*AN$4,0) -> 324 | AO13: =MIN($AN13+$AO$2,MAX($AN13+$AO$3,MAX(0,$AN13/$AL$2*$AJ13))) -> 447.12 | AP13: =AO13+AL13+AM13 -> 1744.12 | AQ13: =AP13-AK13 -> 123.12 | AR13: =AP13/AK13 -> 1.0759531
A14: Muhammed abdul sadaa esa | B14: =VLOOKUP($A14,MainData!$C:$E,2,FALSE) -> Karbala | C14: =COUNTIFS(LO!C:C,$A14) -> 6 | D14: =SUMIFS(LO!F:F,LO!$C:$C,$A14) -> 4219731 | E14: =SUMIFS(LO!G:G,LO!$C:$C,$A14) -> 4666666.7 | F14: =D14/E14 -> 0.90422807 | G14: =SUMIFS(LO!I:I,LO!$C:$C,$A14) -> 1069 | H14: =SUMIFS(LO!J:J,LO!$C:$C,$A14) -> 3200 | I14: =G14/H14 -> 0.3340625 | J14: =SUMIFS(LO!L:L,LO!$C:$C,$A14) -> 291212.12 | K14: =SUMIFS(LO!M:M,LO!$C:$C,$A14) -> 424242.41 | L14: =J14/K14 -> 0.68642859 | M14: =SUMIFS(LO!O:O,LO!$C:$C,$A14) -> 46 | N14: =SUMIFS(LO!P:P,LO!$C:$C,$A14) -> 64 | O14: =M14/N14 -> 0.71875 | P14: =SUMIFS(LO!R:R,LO!$C:$C,$A14) -> 46 | Q14: =SUMIFS(LO!S:S,LO!$C:$C,$A14) -> 25 | R14: =IFERROR(Q14/P14,0) -> 0.54347826 | S14: =SUMIFS(LO!U:U,LO!$C:$C,$A14) -> 13 | T14: =IFERROR((S14)/P14,0) -> 0.2826087 | U14: =SUMIFS(LO!W:W,LO!$C:$C,$A14) -> 1069 | V14: =AVERAGEIFS(LO!X:X,LO!$C:$C,$A14) -> 0.78266667 | W14: =SUMIFS(LO!Y:Y,LO!$C:$C,$A14) -> 130783.55 | X14: =W14/$D14 -> 0.030993338 | Y14: =SUMIFS(LO!AA:AA,LO!$C:$C,$A14) -> 43781.934 | Z14: =Y14/$D14 -> 0.010375527 | AC14: =MAX(0,MIN(AC$2,AC$2*(L14/(AC$3-AC$4)-(AC$4/(AC$3-AC$4))))) -> 0 | AD14: =MAX(0,MIN(AD$2,AD$2*(O14/(AD$3-AD$4)-(AD$4/(AD$3-AD$4))))) -> 0 | AE14: =MIN(AE$2,MAX(0,AE$2-AE$2*(X14/(AE$4-AE$3)-(AE$3/(AE$4-AE$3))))) -> 15.602665 | AF14: =MIN(AF$2,MAX(0,AF$2-AF$2*(Z14/(AF$4-AF$3)-(AF$3/(AF$4-AF$3))))) -> 40 | AG14: =MAX(0,MIN(AG$2,AG$2*(V14/(AG$3-AG$4)-(AG$4/(AG$3-AG$4))))) -> 0 | AH14: =MAX(0,MIN(AH$2,AH$2*(R14/(AH$3-AH$4)-(AH$4/(AH$3-AH$4))))) -> 3.4347826 | AI14: =MAX(0,MIN(AI$2,AI$2*(T14/(AI$3-AI$4)-(AI$4/(AI$3-AI$4))))) -> 4.7101449 | AJ14: =ROUND(SUM(AC14:AI14),0) -> 64 | AK14: 1974 | AL14: =ROUNDUP($AK14*AL$4,0) -> 1185 | AM14: =ROUNDDOWN($AK14*AM$4,0) -> 394 | AN14: =ROUNDDOWN($AK14*AN$4,0) -> 394 | AO14: =MIN($AN14+$AO$2,MAX($AN14+$AO$3,MAX(0,$AN14/$AL$2*$AJ14))) -> 504.32 | AP14: =AO14+AL14+AM14 -> 2083.32 | AQ14: =AP14-AK14 -> 109.32 | AR14: =AP14/AK14 -> 1.0553799
A15: Ali Kareem Hadhil | B15: =VLOOKUP($A15,MainData!$C:$E,2,FALSE) -> Kut | C15: =COUNTIFS(LO!C:C,$A15) -> 5 | D15: =SUMIFS(LO!F:F,LO!$C:$C,$A15) -> 2450390.9 | E15: =SUMIFS(LO!G:G,LO!$C:$C,$A15) -> 2111111.1 | F15: =D15/E15 -> 1.1607115 | G15: =SUMIFS(LO!I:I,LO!$C:$C,$A15) -> 1148 | H15: =SUMIFS(LO!J:J,LO!$C:$C,$A15) -> 2489 | I15: =G15/H15 -> 0.46122941 | J15: =SUMIFS(LO!L:L,LO!$C:$C,$A15) -> 175000 | K15: =SUMIFS(LO!M:M,LO!$C:$C,$A15) -> 306818.17 | L15: =J15/K15 -> 0.57037039 | M15: =SUMIFS(LO!O:O,LO!$C:$C,$A15) -> 52 | N15: =SUMIFS(LO!P:P,LO!$C:$C,$A15) -> 68 | O15: =M15/N15 -> 0.76470588 | P15: =SUMIFS(LO!R:R,LO!$C:$C,$A15) -> 52 | Q15: =SUMIFS(LO!S:S,LO!$C:$C,$A15) -> 23 | R15: =IFERROR(Q15/P15,0) -> 0.44230769 | S15: =SUMIFS(LO!U:U,LO!$C:$C,$A15) -> 36 | T15: =IFERROR((S15)/P15,0) -> 0.69230769 | U15: =SUMIFS(LO!W:W,LO!$C:$C,$A15) -> 1148 | V15: =AVERAGEIFS(LO!X:X,LO!$C:$C,$A15) -> 0.9184 | W15: =SUMIFS(LO!Y:Y,LO!$C:$C,$A15) -> 80971.209 | X15: =W15/$D15 -> 0.0330442 | Y15: =SUMIFS(LO!AA:AA,LO!$C:$C,$A15) -> 38531.561 | Z15: =Y15/$D15 -> 0.015724659 | AC15: =MAX(0,MIN(AC$2,AC$2*(L15/(AC$3-AC$4)-(AC$4/(AC$3-AC$4))))) -> 0 | AD15: =MAX(0,MIN(AD$2,AD$2*(O15/(AD$3-AD$4)-(AD$4/(AD$3-AD$4))))) -> 0 | AE15: =MIN(AE$2,MAX(0,AE$2-AE$2*(X15/(AE$4-AE$3)-(AE$3/(AE$4-AE$3))))) -> 14.78232 | AF15: =MIN(AF$2,MAX(0,AF$2-AF$2*(Z15/(AF$4-AF$3)-(AF$3/(AF$4-AF$3))))) -> 40 | AG15: =MAX(0,MIN(AG$2,AG$2*(V15/(AG$3-AG$4)-(AG$4/(AG$3-AG$4))))) -> 0 | AH15: =MAX(0,MIN(AH$2,AH$2*(R15/(AH$3-AH$4)-(AH$4/(AH$3-AH$4))))) -> 2.4230769 | AI15: =MAX(0,MIN(AI$2,AI$2*(T15/(AI$3-AI$4)-(AI$4/(AI$3-AI$4))))) -> 5 | AJ15: =ROUND(SUM(AC15:AI15),0) -> 62 | AK15: 1170 | AL15: =ROUNDUP($AK15*AL$4,0) -> 702 | AM15: =ROUNDDOWN($AK15*AM$4,0) -> 234 | AN15: =ROUNDDOWN($AK15*AN$4,0) -> 234 | AO15: =MIN($AN15+$AO$2,MAX($AN15+$AO$3,MAX(0,$AN15/$AL$2*$AJ15))) -> 290.16 | AP15: =AO15+AL15+AM15 -> 1226.16 | AQ15: =AP15-AK15 -> 56.16 | AR15: =AP15/AK15 -> 1.048
A16: Hassan Razaq Sebah | B16: =VLOOKUP($A16,MainData!$C:$E,2,FALSE) -> Kut | C16: =COUNTIFS(LO!C:C,$A16) -> 6 | D16: =SUMIFS(LO!F:F,LO!$C:$C,$A16) -> 3582559.6 | E16: =SUMIFS(LO!G:G,LO!$C:$C,$A16) -> 2000000 | F16: =D16/E16 -> 1.7912798 | G16: =SUMIFS(LO!I:I,LO!$C:$C,$A16) -> 1512 | H16: =SUMIFS(LO!J:J,LO!$C:$C,$A16) -> 2400 | I16: =G16/H16 -> 0.63 | J16: =SUMIFS(LO!L:L,LO!$C:$C,$A16) -> 310871.21 | K16: =SUMIFS(LO!M:M,LO!$C:$C,$A16) -> 340909.08 | L16: =J16/K16 -> 0.91188892 | M16: =SUMIFS(LO!O:O,LO!$C:$C,$A16) -> 82 | N16: =SUMIFS(LO!P:P,LO!$C:$C,$A16) -> 90 | O16: =M16/N16 -> 0.91111111 | P16: =SUMIFS(LO!R:R,LO!$C:$C,$A16) -> 82 | Q16: =SUMIFS(LO!S:S,LO!$C:$C,$A16) -> 35 | R16: =IFERROR(Q16/P16,0) -> 0.42682927 | S16: =SUMIFS(LO!U:U,LO!$C:$C,$A16) -> 61 | T16: =IFERROR((S16)/P16,0) -> 0.74390244 | U16: =SUMIFS(LO!W:W,LO!$C:$C,$A16) -> 1512 | V16: =AVERAGEIFS(LO!X:X,LO!$C:$C,$A16) -> 1.008 | W16: =SUMIFS(LO!Y:Y,LO!$C:$C,$A16) -> 36758.753 | X16: =W16/$D16 -> 0.010260472 | Y16: =SUMIFS(LO!AA:AA,LO!$C:$C,$A16) -> 36223.365 | Z16: =Y16/$D16 -> 0.010111029 | AC16: =MAX(0,MIN(AC$2,AC$2*(L16/(AC$3-AC$4)-(AC$4/(AC$3-AC$4))))) -> 21.188892 | AD16: =MAX(0,MIN(AD$2,AD$2*(O16/(AD$3-AD$4)-(AD$4/(AD$3-AD$4))))) -> 0 | AE16: =MIN(AE$2,MAX(0,AE$2-AE$2*(X16/(AE$4-AE$3)-(AE$3/(AE$4-AE$3))))) -> 20 | AF16: =MIN(AF$2,MAX(0,AF$2-AF$2*(Z16/(AF$4-AF$3)-(AF$3/(AF$4-AF$3))))) -> 40 | AG16: =MAX(0,MIN(AG$2,AG$2*(V16/(AG$3-AG$4)-(AG$4/(AG$3-AG$4))))) -> 0 | AH16: =MAX(0,MIN(AH$2,AH$2*(R16/(AH$3-AH$4)-(AH$4/(AH$3-AH$4))))) -> 2.2682927 | AI16: =MAX(0,MIN(AI$2,AI$2*(T16/(AI$3-AI$4)-(AI$4/(AI$3-AI$4))))) -> 5 | AJ16: =ROUND(SUM(AC16:AI16),0) -> 88 | AK16: 1442 | AL16: =ROUNDUP($AK16*AL$4,0) -> 866 | AM16: =ROUNDDOWN($AK16*AM$4,0) -> 288 | AN16: =ROUNDDOWN($AK16*AN$4,0) -> 288 | AO16: =MIN($AN16+$AO$2,MAX($AN16+$AO$3,MAX(0,$AN16/$AL$2*$AJ16))) -> 506.88 | AP16: =AO16+AL16+AM16 -> 1660.88 | AQ16: =AP16-AK16 -> 218.88 | AR16: =AP16/AK16 -> 1.1517892
A17: Hussain Taher Fezaa | B17: =VLOOKUP($A17,MainData!$C:$E,2,FALSE) -> Mansour | C17: =COUNTIFS(LO!C:C,$A17) -> 5 | D17: =SUMIFS(LO!F:F,LO!$C:$C,$A17) -> 3431252.8 | E17: =SUMIFS(LO!G:G,LO!$C:$C,$A17) -> 3888888.9 | F17: =D17/E17 -> 0.88232214 | G17: =SUMIFS(LO!I:I,LO!$C:$C,$A17) -> 766 | H17: =SUMIFS(LO!J:J,LO!$C:$C,$A17) -> 2311 | I17: =G17/H17 -> 0.33145824 | J17: =SUMIFS(LO!L:L,LO!$C:$C,$A17) -> 282196.97 | K17: =SUMIFS(LO!M:M,LO!$C:$C,$A17) -> 344696.96 | L17: =J17/K17 -> 0.81868134 | M17: =SUMIFS(LO!O:O,LO!$C:$C,$A17) -> 32 | N17: =SUMIFS(LO!P:P,LO!$C:$C,$A17) -> 56 | O17: =M17/N17 -> 0.57142857 | P17: =SUMIFS(LO!R:R,LO!$C:$C,$A17) -> 32 | Q17: =SUMIFS(LO!S:S,LO!$C:$C,$A17) -> 20 | R17: =IFERROR(Q17/P17,0) -> 0.625 | S17: =SUMIFS(LO!U:U,LO!$C:$C,$A17) -> 7 | T17: =IFERROR((S17)/P17,0) -> 0.21875 | U17: =SUMIFS(LO!W:W,LO!$C:$C,$A17) -> 766 | V17: =AVERAGEIFS(LO!X:X,LO!$C:$C,$A17) -> 0.6956 | W17: =SUMIFS(LO!Y:Y,LO!$C:$C,$A17) -> 31489.46 | X17: =W17/$D17 -> 0.0091772486 | Y17: =SUMIFS(LO!AA:AA,LO!$C:$C,$A17) -> 70965.276 | Z17: =Y17/$D17 -> 0.020682031 | AC17: =MAX(0,MIN(AC$2,AC$2*(L17/(AC$3-AC$4)-(AC$4/(AC$3-AC$4))))) -> 11.868134 | AD17: =MAX(0,MIN(AD$2,AD$2*(O17/(AD$3-AD$4)-(AD$4/(AD$3-AD$4))))) -> 0 | AE17: =MIN(AE$2,MAX(0,AE$2-AE$2*(X17/(AE$4-AE$3)-(AE$3/(AE$4-AE$3))))) -> 20 | AF17: =MIN(AF$2,MAX(0,AF$2-AF$2*(Z17/(AF$4-AF$3)-(AF$3/(AF$4-AF$3))))) -> 40 | AG17: =MAX(0,MIN(AG$2,AG$2*(V17/(AG$3-AG$4)-(AG$4/(AG$3-AG$4))))) -> 0 | AH17: =MAX(0,MIN(AH$2,AH$2*(R17/(AH$3-AH$4)-(AH$4/(AH$3-AH$4))))) -> 4.25 | AI17: =MAX(0,MIN(AI$2,AI$2*(T17/(AI$3-AI$4)-(AI$4/(AI$3-AI$4))))) -> 3.6458333 | AJ17: =ROUND(SUM(AC17:AI17),0) -> 80 | AK17: 1947 | AL17: =ROUNDUP($AK17*AL$4,0) -> 1169 | AM17: =ROUNDDOWN($AK17*AM$4,0) -> 389 | AN17: =ROUNDDOWN($AK17*AN$4,0) -> 389 | AO17: =MIN($AN17+$AO$2,MAX($AN17+$AO$3,MAX(0,$AN17/$AL$2*$AJ17))) -> 622.4 | AP17: =AO17+AL17+AM17 -> 2180.4 | AQ17: =AP17-AK17 -> 233.4 | AR17: =AP17/AK17 -> 1.1198767
A18: Mohamad Morshid Kadhum | B18: =VLOOKUP($A18,MainData!$C:$E,2,FALSE) -> Mansour | C18: =COUNTIFS(LO!C:C,$A18) -> 5 | D18: =SUMIFS(LO!F:F,LO!$C:$C,$A18) -> 2966019.8 | E18: =SUMIFS(LO!G:G,LO!$C:$C,$A18) -> 3888888.9 | F18: =D18/E18 -> 0.76269081 | G18: =SUMIFS(LO!I:I,LO!$C:$C,$A18) -> 705 | H18: =SUMIFS(LO!J:J,LO!$C:$C,$A18) -> 2311 | I18: =G18/H18 -> 0.30506274 | J18: =SUMIFS(LO!L:L,LO!$C:$C,$A18) -> 175757.58 | K18: =SUMIFS(LO!M:M,LO!$C:$C,$A18) -> 344696.96 | L18: =J18/K18 -> 0.50989012 | M18: =SUMIFS(LO!O:O,LO!$C:$C,$A18) -> 36 | N18: =SUMIFS(LO!P:P,LO!$C:$C,$A18) -> 56 | O18: =M18/N18 -> 0.64285714 | P18: =SUMIFS(LO!R:R,LO!$C:$C,$A18) -> 36 | Q18: =SUMIFS(LO!S:S,LO!$C:$C,$A18) -> 22 | R18: =IFERROR(Q18/P18,0) -> 0.61111111 | S18: =SUMIFS(LO!U:U,LO!$C:$C,$A18) -> 3 | T18: =IFERROR((S18)/P18,0) -> 0.083333333 | U18: =SUMIFS(LO!W:W,LO!$C:$C,$A18) -> 705 | V18: =AVERAGEIFS(LO!X:X,LO!$C:$C,$A18) -> 0.6252 | W18: =SUMIFS(LO!Y:Y,LO!$C:$C,$A18) -> 80254.053 | X18: =W18/$D18 -> 0.027057828 | Y18: =SUMIFS(LO!AA:AA,LO!$C:$C,$A18) -> 60541.596 | Z18: =Y18/$D18 -> 0.02041173 | AC18: =MAX(0,MIN(AC$2,AC$2*(L18/(AC$3-AC$4)-(AC$4/(AC$3-AC$4))))) -> 0 | AD18: =MAX(0,MIN(AD$2,AD$2*(O18/(AD$3-AD$4)-(AD$4/(AD$3-AD$4))))) -> 0 | AE18: =MIN(AE$2,MAX(0,AE$2-AE$2*(X18/(AE$4-AE$3)-(AE$3/(AE$4-AE$3))))) -> 17.176869 | AF18: =MIN(AF$2,MAX(0,AF$2-AF$2*(Z18/(AF$4-AF$3)-(AF$3/(AF$4-AF$3))))) -> 40 | AG18: =MAX(0,MIN(AG$2,AG$2*(V18/(AG$3-AG$4)-(AG$4/(AG$3-AG$4))))) -> 0 | AH18: =MAX(0,MIN(AH$2,AH$2*(R18/(AH$3-AH$4)-(AH$4/(AH$3-AH$4))))) -> 4.1111111 | AI18: =MAX(0,MIN(AI$2,AI$2*(T18/(AI$3-AI$4)-(AI$4/(AI$3-AI$4))))) -> 1.3888889 | AJ18: =ROUND(SUM(AC18:AI18),0) -> 63 | AK18: 1964 | AL18: =ROUNDUP($AK18*AL$4,0) -> 1179 | AM18: =ROUNDDOWN($AK18*AM$4,0) -> 392 | AN18: =ROUNDDOWN($AK18*AN$4,0) -> 392 | AO18: =MIN($AN18+$AO$2,MAX($AN18+$AO$3,MAX(0,$AN18/$AL$2*$AJ18))) -> 493.92 | AP18: =AO18+AL18+AM18 -> 2064.92 | AQ18: =AP18-AK18 -> 100.92 | AR18: =AP18/AK18 -> 1.0513849
A19: Methaq Abdul Amir Jasim | B19: Mudaina | C19: =COUNTIFS(LO!C:C,$A19) -> 6 | D19: =SUMIFS(LO!F:F,LO!$C:$C,$A19) -> 3419744.8 | E19: =SUMIFS(LO!G:G,LO!$C:$C,$A19) -> 2000000 | F19: =D19/E19 -> 1.7098724 | G19: =SUMIFS(LO!I:I,LO!$C:$C,$A19) -> 1080 | H19: =SUMIFS(LO!J:J,LO!$C:$C,$A19) -> 2400 | I19: =G19/H19 -> 0.45 | J19: =SUMIFS(LO!L:L,LO!$C:$C,$A19) -> 293787.88 | K19: =SUMIFS(LO!M:M,LO!$C:$C,$A19) -> 340909.08 | L19: =J19/K19 -> 0.86177781 | M19: =SUMIFS(LO!O:O,LO!$C:$C,$A19) -> 61 | N19: =SUMIFS(LO!P:P,LO!$C:$C,$A19) -> 90 | O19: =M19/N19 -> 0.67777778 | P19: =SUMIFS(LO!R:R,LO!$C:$C,$A19) -> 61 | Q19: =SUMIFS(LO!S:S,LO!$C:$C,$A19) -> 36 | R19: =IFERROR(Q19/P19,0) -> 0.59016393 | S19: =SUMIFS(LO!U:U,LO!$C:$C,$A19) -> 22 | T19: =IFERROR((S19)/P19,0) -> 0.36065574 | U19: =SUMIFS(LO!W:W,LO!$C:$C,$A19) -> 1080 | V19: =AVERAGEIFS(LO!X:X,LO!$C:$C,$A19) -> 0.72 | W19: =SUMIFS(LO!Y:Y,LO!$C:$C,$A19) -> 5135.5224 | X19: =W19/$D19 -> 0.0015017268 | Y19: =SUMIFS(LO!AA:AA,LO!$C:$C,$A19) -> 74988.577 | Z19: =Y19/$D19 -> 0.021928121 | AC19: =MAX(0,MIN(AC$2,AC$2*(L19/(AC$3-AC$4)-(AC$4/(AC$3-AC$4))))) -> 16.177781 | AD19: =MAX(0,MIN(AD$2,AD$2*(O19/(AD$3-AD$4)-(AD$4/(AD$3-AD$4))))) -> 0 | AE19: =MIN(AE$2,MAX(0,AE$2-AE$2*(X19/(AE$4-AE$3)-(AE$3/(AE$4-AE$3))))) -> 20 | AF19: =MIN(AF$2,MAX(0,AF$2-AF$2*(Z19/(AF$4-AF$3)-(AF$3/(AF$4-AF$3))))) -> 40 | AG19: =MAX(0,MIN(AG$2,AG$2*(V19/(AG$3-AG$4)-(AG$4/(AG$3-AG$4))))) -> 0 | AH19: =MAX(0,MIN(AH$2,AH$2*(R19/(AH$3-AH$4)-(AH$4/(AH$3-AH$4))))) -> 3.9016393 | AI19: =MAX(0,MIN(AI$2,AI$2*(T19/(AI$3-AI$4)-(AI$4/(AI$3-AI$4))))) -> 5 | AJ19: =ROUND(SUM(AC19:AI19),0) -> 85 | AK19: 1301 | AL19: =ROUNDUP($AK19*AL$4,0) -> 781 | AM19: =ROUNDDOWN($AK19*AM$4,0) -> 260 | AN19: =ROUNDDOWN($AK19*AN$4,0) -> 260 | AO19: =MIN($AN19+$AO$2,MAX($AN19+$AO$3,MAX(0,$AN19/$AL$2*$AJ19))) -> 442 | AP19: =AO19+AL19+AM19 -> 1483 | AQ19: =AP19-AK19 -> 182 | AR19: =AP19/AK19 -> 1.1398924
A20: Abbas Razaq Abdul Razaq | B20: =VLOOKUP($A20,MainData!$C:$E,2,FALSE) -> Najaf | C20: =COUNTIFS(LO!C:C,$A20) -> 4 | D20: =SUMIFS(LO!F:F,LO!$C:$C,$A20) -> 2746481.2 | E20: =SUMIFS(LO!G:G,LO!$C:$C,$A20) -> 3555555.6 | F20: =D20/E20 -> 0.77244783 | G20: =SUMIFS(LO!I:I,LO!$C:$C,$A20) -> 461 | H20: =SUMIFS(LO!J:J,LO!$C:$C,$A20) -> 1911 | I20: =G20/H20 -> 0.24123496 | J20: =SUMIFS(LO!L:L,LO!$C:$C,$A20) -> 242727.27 | K20: =SUMIFS(LO!M:M,LO!$C:$C,$A20) -> 287878.78 | L20: =J20/K20 -> 0.84315792 | M20: =SUMIFS(LO!O:O,LO!$C:$C,$A20) -> 40 | N20: =SUMIFS(LO!P:P,LO!$C:$C,$A20) -> 41 | O20: =M20/N20 -> 0.97560976 | P20: =SUMIFS(LO!R:R,LO!$C:$C,$A20) -> 40 | Q20: =SUMIFS(LO!S:S,LO!$C:$C,$A20) -> 27 | R20: =IFERROR(Q20/P20,0) -> 0.675 | S20: =SUMIFS(LO!U:U,LO!$C:$C,$A20) -> 18 | T20: =IFERROR((S20)/P20,0) -> 0.45 | U20: =SUMIFS(LO!W:W,LO!$C:$C,$A20) -> 461 | V20: =AVERAGEIFS(LO!X:X,LO!$C:$C,$A20) -> 0.554 | W20: =SUMIFS(LO!Y:Y,LO!$C:$C,$A20) -> 69701.435 | X20: =W20/$D20 -> 0.02537845 | Y20: =SUMIFS(LO!AA:AA,LO!$C:$C,$A20) -> 21626.055 | Z20: =Y20/$D20 -> 0.0078740956 | AC20: =MAX(0,MIN(AC$2,AC$2*(L20/(AC$3-AC$4)-(AC$4/(AC$3-AC$4))))) -> 14.315792 | AD20: =MAX(0,MIN(AD$2,AD$2*(O20/(AD$3-AD$4)-(AD$4/(AD$3-AD$4))))) -> 0 | AE20: =MIN(AE$2,MAX(0,AE$2-AE$2*(X20/(AE$4-AE$3)-(AE$3/(AE$4-AE$3))))) -> 17.84862 | AF20: =MIN(AF$2,MAX(0,AF$2-AF$2*(Z20/(AF$4-AF$3)-(AF$3/(AF$4-AF$3))))) -> 40 | AG20: =MAX(0,MIN(AG$2,AG$2*(V20/(AG$3-AG$4)-(AG$4/(AG$3-AG$4))))) -> 0 | AH20: =MAX(0,MIN(AH$2,AH$2*(R20/(AH$3-AH$4)-(AH$4/(AH$3-AH$4))))) -> 4.75 | AI20: =MAX(0,MIN(AI$2,AI$2*(T20/(AI$3-AI$4)-(AI$4/(AI$3-AI$4))))) -> 5 | AJ20: =ROUND(SUM(AC20:AI20),0) -> 82 | AK20: 1733 | AL20: =ROUNDUP($AK20*AL$4,0) -> 1040 | AM20: =ROUNDDOWN($AK20*AM$4,0) -> 346 | AN20: =ROUNDDOWN($AK20*AN$4,0) -> 346 | AO20: =MIN($AN20+$AO$2,MAX($AN20+$AO$3,MAX(0,$AN20/$AL$2*$AJ20))) -> 567.44 | AP20: =AO20+AL20+AM20 -> 1953.44 | AQ20: =AP20-AK20 -> 220.44 | AR20: =AP20/AK20 -> 1.1272014
A21: Ahmed Hilal Abdul Kareem | B21: =VLOOKUP($A21,MainData!$C:$E,2,FALSE) -> Najaf | C21: =COUNTIFS(LO!C:C,$A21) -> 5 | D21: =SUMIFS(LO!F:F,LO!$C:$C,$A21) -> 3341219.5 | E21: =SUMIFS(LO!G:G,LO!$C:$C,$A21) -> 4333333.3 | F21: =D21/E21 -> 0.77105066 | G21: =SUMIFS(LO!I:I,LO!$C:$C,$A21) -> 676 | H21: =SUMIFS(LO!J:J,LO!$C:$C,$A21) -> 2800 | I21: =G21/H21 -> 0.24142857 | J21: =SUMIFS(LO!L:L,LO!$C:$C,$A21) -> 122537.88 | K21: =SUMIFS(LO!M:M,LO!$C:$C,$A21) -> 367424.23 | L21: =J21/K21 -> 0.33350517 | M21: =SUMIFS(LO!O:O,LO!$C:$C,$A21) -> 24 | N21: =SUMIFS(LO!P:P,LO!$C:$C,$A21) -> 49 | O21: =M21/N21 -> 0.48979592 | P21: =SUMIFS(LO!R:R,LO!$C:$C,$A21) -> 24 | Q21: =SUMIFS(LO!S:S,LO!$C:$C,$A21) -> 12 | R21: =IFERROR(Q21/P21,0) -> 0.5 | S21: =SUMIFS(LO!U:U,LO!$C:$C,$A21) -> 14 | T21: =IFERROR((S21)/P21,0) -> 0.58333333 | U21: =SUMIFS(LO!W:W,LO!$C:$C,$A21) -> 676 | V21: =AVERAGEIFS(LO!X:X,LO!$C:$C,$A21) -> 0.5984 | W21: =SUMIFS(LO!Y:Y,LO!$C:$C,$A21) -> 143870.77 | X21: =W21/$D21 -> 0.043059359 | Y21: =SUMIFS(LO!AA:AA,LO!$C:$C,$A21) -> 166491.05 | Z21: =Y21/$D21 -> 0.049829425 | AC21: =MAX(0,MIN(AC$2,AC$2*(L21/(AC$3-AC$4)-(AC$4/(AC$3-AC$4))))) -> 0 | AD21: =MAX(0,MIN(AD$2,AD$2*(O21/(AD$3-AD$4)-(AD$4/(AD$3-AD$4))))) -> 0 | AE21: =MIN(AE$2,MAX(0,AE$2-AE$2*(X21/(AE$4-AE$3)-(AE$3/(AE$4-AE$3))))) -> 10.776256 | AF21: =MIN(AF$2,MAX(0,AF$2-AF$2*(Z21/(AF$4-AF$3)-(AF$3/(AF$4-AF$3))))) -> 40 | AG21: =MAX(0,MIN(AG$2,AG$2*(V21/(AG$3-AG$4)-(AG$4/(AG$3-AG$4))))) -> 0 | AH21: =MAX(0,MIN(AH$2,AH$2*(R21/(AH$3-AH$4)-(AH$4/(AH$3-AH$4))))) -> 3 | AI21: =MAX(0,MIN(AI$2,AI$2*(T21/(AI$3-AI$4)-(AI$4/(AI$3-AI$4))))) -> 5 | AJ21: =ROUND(SUM(AC21:AI21),0) -> 59 | AK21: 1990 | AL21: =ROUNDUP($AK21*AL$4,0) -> 1194 | AM21: =ROUNDDOWN($AK21*AM$4,0) -> 398 | AN21: =ROUNDDOWN($AK21*AN$4,0) -> 398 | AO21: =MIN($AN21+$AO$2,MAX($AN21+$AO$3,MAX(0,$AN21/$AL$2*$AJ21))) -> 469.64 | AP21: =AO21+AL21+AM21 -> 2061.64 | AQ21: =AP21-AK21 -> 71.64 | AR21: =AP21/AK21 -> 1.036
A22: Azhar Hassan Hussien | B22: =VLOOKUP($A22,MainData!$C:$E,2,FALSE) -> Najaf | C22: =COUNTIFS(LO!C:C,$A22) -> 2 | D22: =SUMIFS(LO!F:F,LO!$C:$C,$A22) -> 1163428.6 | E22: =SUMIFS(LO!G:G,LO!$C:$C,$A22) -> 1111111.1 | F22: =D22/E22 -> 1.0470857 | G22: =SUMIFS(LO!I:I,LO!$C:$C,$A22) -> 353 | H22: =SUMIFS(LO!J:J,LO!$C:$C,$A22) -> 1289 | I22: =G22/H22 -> 0.2738557 | J22: =SUMIFS(LO!L:L,LO!$C:$C,$A22) -> 57575.758 | K22: =SUMIFS(LO!M:M,LO!$C:$C,$A22) -> 136363.63 | L22: =J22/K22 -> 0.42222224 | M22: =SUMIFS(LO!O:O,LO!$C:$C,$A22) -> 15 | N22: =SUMIFS(LO!P:P,LO!$C:$C,$A22) -> 23 | O22: =M22/N22 -> 0.65217391 | P22: =SUMIFS(LO!R:R,LO!$C:$C,$A22) -> 15 | Q22: =SUMIFS(LO!S:S,LO!$C:$C,$A22) -> 8 | R22: =IFERROR(Q22/P22,0) -> 0.53333333 | S22: =SUMIFS(LO!U:U,LO!$C:$C,$A22) -> 13 | T22: =IFERROR((S22)/P22,0) -> 0.86666667 | U22: =SUMIFS(LO!W:W,LO!$C:$C,$A22) -> 353 | V22: =AVERAGEIFS(LO!X:X,LO!$C:$C,$A22) -> 0.706 | W22: =SUMIFS(LO!Y:Y,LO!$C:$C,$A22) -> 31554.445 | X22: =W22/$D22 -> 0.027121943 | Y22: =SUMIFS(LO!AA:AA,LO!$C:$C,$A22) -> 126566.31 | Z22: =Y22/$D22 -> 0.10878735 | AC22: =MAX(0,MIN(AC$2,AC$2*(L22/(AC$3-AC$4)-(AC$4/(AC$3-AC$4))))) -> 0 | AD22: =MAX(0,MIN(AD$2,AD$2*(O22/(AD$3-AD$4)-(AD$4/(AD$3-AD$4))))) -> 0 | AE22: =MIN(AE$2,MAX(0,AE$2-AE$2*(X22/(AE$4-AE$3)-(AE$3/(AE$4-AE$3))))) -> 17.151223 | AF22: =MIN(AF$2,MAX(0,AF$2-AF$2*(Z22/(AF$4-AF$3)-(AF$3/(AF$4-AF$3))))) -> 16.485061 | AG22: =MAX(0,MIN(AG$2,AG$2*(V22/(AG$3-AG$4)-(AG$4/(AG$3-AG$4))))) -> 0 | AH22: =MAX(0,MIN(AH$2,AH$2*(R22/(AH$3-AH$4)-(AH$4/(AH$3-AH$4))))) -> 3.3333333 | AI22: =MAX(0,MIN(AI$2,AI$2*(T22/(AI$3-AI$4)-(AI$4/(AI$3-AI$4))))) -> 5 | AJ22: =ROUND(SUM(AC22:AI22),0) -> 42 | AK22: 1444 | AL22: =ROUNDUP($AK22*AL$4,0) -> 867 | AM22: =ROUNDDOWN($AK22*AM$4,0) -> 288 | AN22: =ROUNDDOWN($AK22*AN$4,0) -> 288 | AO22: =MIN($AN22+$AO$2,MAX($AN22+$AO$3,MAX(0,$AN22/$AL$2*$AJ22))) -> 241.92 | AP22: =AO22+AL22+AM22 -> 1396.92 | AQ22: =AP22-AK22 -> -47.08 | AR22: =AP22/AK22 -> 0.96739612
A23: Khalid Mousa Jumaa | B23: =VLOOKUP($A23,MainData!$C:$E,2,FALSE) -> Nasriya | C23: =COUNTIFS(LO!C:C,$A23) -> 5 | D23: =SUMIFS(LO!F:F,LO!$C:$C,$A23) -> 3368007.6 | E23: =SUMIFS(LO!G:G,LO!$C:$C,$A23) -> 3000000 | F23: =D23/E23 -> 1.1226692 | G23: =SUMIFS(LO!I:I,LO!$C:$C,$A23) -> 894 | H23: =SUMIFS(LO!J:J,LO!$C:$C,$A23) -> 3467 | I23: =G23/H23 -> 0.25785982 | J23: =SUMIFS(LO!L:L,LO!$C:$C,$A23) -> 305757.58 | K23: =SUMIFS(LO!M:M,LO!$C:$C,$A23) -> 352272.71 | L23: =J23/K23 -> 0.86795703 | M23: =SUMIFS(LO!O:O,LO!$C:$C,$A23) -> 59 | N23: =SUMIFS(LO!P:P,LO!$C:$C,$A23) -> 54 | O23: =M23/N23 -> 1.0925926 | P23: =SUMIFS(LO!R:R,LO!$C:$C,$A23) -> 59 | Q23: =SUMIFS(LO!S:S,LO!$C:$C,$A23) -> 21 | R23: =IFERROR(Q23/P23,0) -> 0.3559322 | S23: =SUMIFS(LO!U:U,LO!$C:$C,$A23) -> 23 | T23: =IFERROR((S23)/P23,0) -> 0.38983051 | U23: =SUMIFS(LO!W:W,LO!$C:$C,$A23) -> 894 | V23: =AVERAGEIFS(LO!X:X,LO!$C:$C,$A23) -> 0.7152 | W23: =SUMIFS(LO!Y:Y,LO!$C:$C,$A23) -> 151146.41 | X23: =W23/$D23 -> 0.044877099 | Y23: =SUMIFS(LO!AA:AA,LO!$C:$C,$A23) -> 17797.783 | Z23: =Y23/$D23 -> 0.0052843656 | AC23: =MAX(0,MIN(AC$2,AC$2*(L23/(AC$3-AC$4)-(AC$4/(AC$3-AC$4))))) -> 16.795703 | AD23: =MAX(0,MIN(AD$2,AD$2*(O23/(AD$3-AD$4)-(AD$4/(AD$3-AD$4))))) -> 0 | AE23: =MIN(AE$2,MAX(0,AE$2-AE$2*(X23/(AE$4-AE$3)-(AE$3/(AE$4-AE$3))))) -> 10.04916 | AF23: =MIN(AF$2,MAX(0,AF$2-AF$2*(Z23/(AF$4-AF$3)-(AF$3/(AF$4-AF$3))))) -> 40 | AG23: =MAX(0,MIN(AG$2,AG$2*(V23/(AG$3-AG$4)-(AG$4/(AG$3-AG$4))))) -> 0 | AH23: =MAX(0,MIN(AH$2,AH$2*(R23/(AH$3-AH$4)-(AH$4/(AH$3-AH$4))))) -> 1.559322 | AI23: =MAX(0,MIN(AI$2,AI$2*(T23/(AI$3-AI$4)-(AI$4/(AI$3-AI$4))))) -> 5 | AJ23: =ROUND(SUM(AC23:AI23),0) -> 73 | AK23: 1915 | AL23: =ROUNDUP($AK23*AL$4,0) -> 1149 | AM23: =ROUNDDOWN($AK23*AM$4,0) -> 383 | AN23: =ROUNDDOWN($AK23*AN$4,0) -> 383 | AO23: =MIN($AN23+$AO$2,MAX($AN23+$AO$3,MAX(0,$AN23/$AL$2*$AJ23))) -> 559.18 | AP23: =AO23+AL23+AM23 -> 2091.18 | AQ23: =AP23-AK23 -> 176.18 | AR23: =AP23/AK23 -> 1.092
A24: Ahmed Hadi Muhammad | B24: =VLOOKUP($A24,MainData!$C:$E,2,FALSE) -> Nasriya | C24: =COUNTIFS(LO!C:C,$A24) -> 4 | D24: =SUMIFS(LO!F:F,LO!$C:$C,$A24) -> 2502578.3 | E24: =SUMIFS(LO!G:G,LO!$C:$C,$A24) -> 1777777.8 | F24: =D24/E24 -> 1.4077003 | G24: =SUMIFS(LO!I:I,LO!$C:$C,$A24) -> 793 | H24: =SUMIFS(LO!J:J,LO!$C:$C,$A24) -> 2089 | I24: =G24/H24 -> 0.37960747 | J24: =SUMIFS(LO!L:L,LO!$C:$C,$A24) -> 272045.45 | K24: =SUMIFS(LO!M:M,LO!$C:$C,$A24) -> 249999.99 | L24: =J24/K24 -> 1.0881819 | M24: =SUMIFS(LO!O:O,LO!$C:$C,$A24) -> 54 | N24: =SUMIFS(LO!P:P,LO!$C:$C,$A24) -> 53 | O24: =M24/N24 -> 1.0188679 | P24: =SUMIFS(LO!R:R,LO!$C:$C,$A24) -> 54 | Q24: =SUMIFS(LO!S:S,LO!$C:$C,$A24) -> 24 | R24: =IFERROR(Q24/P24,0) -> 0.44444444 | S24: =SUMIFS(LO!U:U,LO!$C:$C,$A24) -> 35 | T24: =IFERROR((S24)/P24,0) -> 0.64814815 | U24: =SUMIFS(LO!W:W,LO!$C:$C,$A24) -> 793 | V24: =AVERAGEIFS(LO!X:X,LO!$C:$C,$A24) -> 0.793 | W24: =SUMIFS(LO!Y:Y,LO!$C:$C,$A24) -> 100924.01 | X24: =W24/$D24 -> 0.040328012 | Y24: =SUMIFS(LO!AA:AA,LO!$C:$C,$A24) -> 26543.89 | Z24: =Y24/$D24 -> 0.010606617 | AC24: =MAX(0,MIN(AC$2,AC$2*(L24/(AC$3-AC$4)-(AC$4/(AC$3-AC$4))))) -> 30 | AD24: =MAX(0,MIN(AD$2,AD$2*(O24/(AD$3-AD$4)-(AD$4/(AD$3-AD$4))))) -> 0 | AE24: =MIN(AE$2,MAX(0,AE$2-AE$2*(X24/(AE$4-AE$3)-(AE$3/(AE$4-AE$3))))) -> 11.868795 | AF24: =MIN(AF$2,MAX(0,AF$2-AF$2*(Z24/(AF$4-AF$3)-(AF$3/(AF$4-AF$3))))) -> 40 | AG24: =MAX(0,MIN(AG$2,AG$2*(V24/(AG$3-AG$4)-(AG$4/(AG$3-AG$4))))) -> 0 | AH24: =MAX(0,MIN(AH$2,AH$2*(R24/(AH$3-AH$4)-(AH$4/(AH$3-AH$4))))) -> 2.4444444 | AI24: =MAX(0,MIN(AI$2,AI$2*(T24/(AI$3-AI$4)-(AI$4/(AI$3-AI$4))))) -> 5 | AJ24: =ROUND(SUM(AC24:AI24),0) -> 89 | AK24: 1972 | AL24: =ROUNDUP($AK24*AL$4,0) -> 1184 | AM24: =ROUNDDOWN($AK24*AM$4,0) -> 394 | AN24: =ROUNDDOWN($AK24*AN$4,0) -> 394 | AO24: =MIN($AN24+$AO$2,MAX($AN24+$AO$3,MAX(0,$AN24/$AL$2*$AJ24))) -> 694 | AP24: =AO24+AL24+AM24 -> 2272 | AQ24: =AP24-AK24 -> 300 | AR24: =AP24/AK24 -> 1.1521298
